Workbook

Sheet Methodology
B2: Methodology
B5: 1. Download CEPII Data -> more than 8mn rows --> need to load as Pivot Table
B6: 2. Select prduct - anhydrous ammonia as best proxy for exisiting hydrogen export strucutre since closest concerning special requirements for export (temperature and pressurized storage) for 2024 - import quantity of export
B7: 3. Apply country codes to map to database

Sheet Ouput>>

Sheet Output
B2: Metric Tons of anhydrous Ammonia exported per country
B4: Approach: | C4: Xlookup the countries from the database - if not found, then manually add name. When more than one country, average the score. If not found, value of 0 assumed
B6: ISO | C6: Country | D6: Total | F6: Helper 1 | G6: Helper 2 | H6: Helper 3 | J6: Country Helper 1 | K6: Country Helper 2 | L6: Country Helper 3
B7: NLD | C7: Netherlands | D7: =_xlfn.XLOOKUP(B7,'ED_CEPII Data'!$B$5:$B$92,'ED_CEPII Data'!$C$5:$C$92,0,0,1) -> 477720861
B8: NOR | C8: Norway | D8: =_xlfn.XLOOKUP(B8,'ED_CEPII Data'!$B$5:$B$92,'ED_CEPII Data'!$C$5:$C$92,0,0,1) -> 32
B9: SWE | C9: Sweden | D9: =_xlfn.XLOOKUP(B9,'ED_CEPII Data'!$B$5:$B$92,'ED_CEPII Data'!$C$5:$C$92,0,0,1) -> 1760215
B10: ESP | C10: Spain | D10: =_xlfn.XLOOKUP(B10,'ED_CEPII Data'!$B$5:$B$92,'ED_CEPII Data'!$C$5:$C$92,0,0,1) -> 96795596
B11: USA | C11: United States | D11: =_xlfn.XLOOKUP(B11,'ED_CEPII Data'!$B$5:$B$92,'ED_CEPII Data'!$C$5:$C$92,0,0,1) -> 1327123766
B12: JPN | C12: Japan | D12: =_xlfn.XLOOKUP(B12,'ED_CEPII Data'!$B$5:$B$92,'ED_CEPII Data'!$C$5:$C$92,0,0,1) -> 99311
B13: CHE | C13: Switzerland | D13: =_xlfn.XLOOKUP(B13,'ED_CEPII Data'!$B$5:$B$92,'ED_CEPII Data'!$C$5:$C$92,0,0,1) -> 2107350
B14: DEU | C14: Germany | D14: =_xlfn.XLOOKUP(B14,'ED_CEPII Data'!$B$5:$B$92,'ED_CEPII Data'!$C$5:$C$92,0,0,1) -> 475065757
B15: GBR | C15: United Kingdom | D15: =_xlfn.XLOOKUP(B15,'ED_CEPII Data'!$B$5:$B$92,'ED_CEPII Data'!$C$5:$C$92,0,0,1) -> 90600061
B16: DNK | C16: Denmark | D16: =_xlfn.XLOOKUP(B16,'ED_CEPII Data'!$B$5:$B$92,'ED_CEPII Data'!$C$5:$C$92,0,0,1) -> 483641
B17: AUT | C17: Austria | D17: =_xlfn.XLOOKUP(B17,'ED_CEPII Data'!$B$5:$B$92,'ED_CEPII Data'!$C$5:$C$92,0,0,1) -> 3352763
B18: CHN | C18: China | D18: =_xlfn.XLOOKUP(B18,'ED_CEPII Data'!$B$5:$B$92,'ED_CEPII Data'!$C$5:$C$92,0,0,1) -> 42493270
... B107: LCA | C107: Saint Lucia | D107: =_xlfn.XLOOKUP(B107,'ED_CEPII Data'!$B$5:$B$92,'ED_CEPII Data'!$C$5:$C$92,0,0,1) -> 0
B108: PRT ESP | C108: #N/A | D108: =AVERAGE(F108:H108) -> 58751836 | F108: =_xlfn.XLOOKUP(J108,$B$7:$B$107,$D$7:$D$107,"N/A",0,1) -> 20708077 | G108: =_xlfn.XLOOKUP(K108,$B$7:$B$107,$D$7:$D$107,"N/A",0,1) -> 96795596 | J108: PRT | K108: ESP
B109: ROM DEU AUT | C109: #N/A | D109: =AVERAGE(F109:H109) -> 239209260 | G109: =_xlfn.XLOOKUP(K109,$B$7:$B$107,$D$7:$D$107,"N/A",0,1) -> 475065757 | H109: =_xlfn.XLOOKUP(L109,$B$7:$B$107,$D$7:$D$107,"N/A",0,1) -> 3352763 | J109: ROM | K109: DEU | L109: AUT
B110: POL CZE SVK HUN | C110: #N/A | D110: =AVERAGE(F110:H110) -> 29644023 | F110: =_xlfn.XLOOKUP(J110,$B$7:$B$107,$D$7:$D$107,"N/A",0,1) -> 20484949 | G110: =_xlfn.XLOOKUP(K110,$B$7:$B$107,$D$7:$D$107,"N/A",0,1) -> 25669136 | H110: =_xlfn.XLOOKUP(L110,$B$7:$B$107,$D$7:$D$107,"N/A",0,1) -> 42777985 | J110: POL | K110: CZE | L110: SVK
B111: DEU DNK | C111: #N/A | D111: =AVERAGE(F111:H111) -> 237774699 | F111: =_xlfn.XLOOKUP(J111,$B$7:$B$107,$D$7:$D$107,"N/A",0,1) -> 475065757 | G111: =_xlfn.XLOOKUP(K111,$B$7:$B$107,$D$7:$D$107,"N/A",0,1) -> 483641 | J111: DEU | K111: DNK
B112: ESP FRA | C112: #N/A | D112: =AVERAGE(F112:H112) -> 95331283 | F112: =_xlfn.XLOOKUP(J112,$B$7:$B$107,$D$7:$D$107,"N/A",0,1) -> 96795596 | G112: =_xlfn.XLOOKUP(K112,$B$7:$B$107,$D$7:$D$107,"N/A",0,1) -> 93866970 | J112: ESP | K112: FRA

Sheet Transformed>>

Sheet ED_CEPII Data
A1: Product | B1: 281410 | C1: Ammonia: anhydrous
A2: Year | B2: 2024
A4: Row Labels | B4: Country ISO 3 Code | C4: Metric Tons (q) | D4: Log of q
A5: 12 | B5: =_xlfn.XLOOKUP(A5,'ED_Country Codes'!$A$2:$A$239,'ED_Country Codes'!$D$2:$D$239,"N/A",0,1) -> DZA | C5: 66890227 | D5: =LOG(C5) -> 7.8253627
A6: 24 | B6: =_xlfn.XLOOKUP(A6,'ED_Country Codes'!$A$2:$A$239,'ED_Country Codes'!$D$2:$D$239,"N/A",0,1) -> AGO | C6: 594 | D6: =LOG(C6) -> 2.7737864
A7: 32 | B7: =_xlfn.XLOOKUP(A7,'ED_Country Codes'!$A$2:$A$239,'ED_Country Codes'!$D$2:$D$239,"N/A",0,1) -> ARG | C7: 558834 | D7: =LOG(C7) -> 5.7472828
A8: 36 | B8: =_xlfn.XLOOKUP(A8,'ED_Country Codes'!$A$2:$A$239,'ED_Country Codes'!$D$2:$D$239,"N/A",0,1) -> AUS | C8: 244111412 | D8: =LOG(C8) -> 8.3875881
A9: 40 | B9: =_xlfn.XLOOKUP(A9,'ED_Country Codes'!$A$2:$A$239,'ED_Country Codes'!$D$2:$D$239,"N/A",0,1) -> AUT | C9: 3352763 | D9: =LOG(C9) -> 6.5254029
A10: 48 | B10: =_xlfn.XLOOKUP(A10,'ED_Country Codes'!$A$2:$A$239,'ED_Country Codes'!$D$2:$D$239,"N/A",0,1) -> BHR | C10: 15837538 | D10: =LOG(C10) -> 7.1996877
A11: 50 | B11: =_xlfn.XLOOKUP(A11,'ED_Country Codes'!$A$2:$A$239,'ED_Country Codes'!$D$2:$D$239,"N/A",0,1) -> BGD | C11: 896464 | D11: =LOG(C11) -> 5.9525329
A12: 56 | B12: =_xlfn.XLOOKUP(A12,'ED_Country Codes'!$A$2:$A$239,'ED_Country Codes'!$D$2:$D$239,"N/A",0,1) -> BEL | C12: 80926336 | D12: =LOG(C12) -> 7.9080899
A13: 76 | B13: =_xlfn.XLOOKUP(A13,'ED_Country Codes'!$A$2:$A$239,'ED_Country Codes'!$D$2:$D$239,"N/A",0,1) -> BRA | C13: 240 | D13: =LOG(C13) -> 2.3802112
A14: 100 | B14: =_xlfn.XLOOKUP(A14,'ED_Country Codes'!$A$2:$A$239,'ED_Country Codes'!$D$2:$D$239,"N/A",0,1) -> BGR | C14: 57268331 | D14: =LOG(C14) -> 7.7579145
A15: 116 | B15: =_xlfn.XLOOKUP(A15,'ED_Country Codes'!$A$2:$A$239,'ED_Country Codes'!$D$2:$D$239,"N/A",0,1) -> KHM | C15: 213 | D15: =LOG(C15) -> 2.3283796
A16: 124 | B16: =_xlfn.XLOOKUP(A16,'ED_Country Codes'!$A$2:$A$239,'ED_Country Codes'!$D$2:$D$239,"N/A",0,1) -> CAN | C16: 1081034591 | D16: =LOG(C16) -> 9.0338396
... A92: 894 | B92: =_xlfn.XLOOKUP(A92,'ED_Country Codes'!$A$2:$A$239,'ED_Country Codes'!$D$2:$D$239,"N/A",0,1) -> ZMB | C92: 3 | D92: =LOG(C92) -> 0.47712125
A93: Grand Total | B93: =_xlfn.XLOOKUP(A93,'ED_Country Codes'!$A$2:$A$239,'ED_Country Codes'!$D$2:$D$239,"N/A",0,1) -> N/A | C93: 8800243189

Sheet ED_Country Codes
A1: country_code | B1: country_name | C1: country_iso2 | D1: country_iso3
A2: 4 | B2: Afghanistan | C2: AF | D2: AFG
A3: 8 | B3: Albania | C3: AL | D3: ALB
A4: 12 | B4: Algeria | C4: DZ | D4: DZA
A5: 16 | B5: American Samoa | C5: AS | D5: ASM
A6: 20 | B6: Andorra | C6: AD | D6: AND
A7: 24 | B7: Angola | C7: AO | D7: AGO
A8: 28 | B8: Antigua and Barbuda | C8: AG | D8: ATG
A9: 31 | B9: Azerbaijan | C9: AZ | D9: AZE
A10: 32 | B10: Argentina | C10: AR | D10: ARG
A11: 36 | B11: Australia | C11: AU | D11: AUS
A12: 40 | B12: Austria | C12: AT | D12: AUT
A13: 44 | B13: Bahamas | C13: BS | D13: BHS
... A131: 484 | B131: Mexico | C131: MX | D131: MEX
A132: 490 | B132: Other Asia, nes | D132: S19
A133: 496 | B133: Mongolia | C133: MN | D133: MNG
A134: 498 | B134: Rep. of Moldova | C134: MD | D134: MDA
A135: 499 | B135: Montenegro | C135: ME | D135: MNE
A136: 500 | B136: Montserrat | C136: MS | D136: MSR
A137: 504 | B137: Morocco | C137: MA | D137: MAR
A138: 508 | B138: Mozambique | C138: MZ | D138: MOZ
A139: 512 | B139: Oman | C139: OM | D139: OMN
A140: 516 | B140: Namibia | D140: NAM
A141: 520 | B141: Nauru | C141: NR | D141: NRU
A142: 524 | B142: Nepal | C142: NP | D142: NPL
A143: 528 | B143: Netherlands | C143: NL | D143: NLD
A144: 530 | B144: Netherlands Antilles (...2010) | C144: AN | D144: ANT
A145: 531 | B145: CuraÃƒÂ§ao | C145: CW | D145: CUW
A146: 533 | B146: Aruba | C146: AW | D146: ABW
A147: 534 | B147: Saint Maarten | C147: SX | D147: SXM
A148: 535 | B148: Bonaire | C148: BQ | D148: BES
A149: 540 | B149: New Caledonia | C149: NC | D149: NCL
A150: 548 | B150: Vanuatu | C150: VU | D150: VUT
A151: 554 | B151: New Zealand | C151: NZ | D151: NZL
A152: 558 | B152: Nicaragua | C152: NI | D152: NIC
... A190: 694 | B190: Sierra Leone | C190: SL | D190: SLE
A191: 697 | B191: Europe EFTA, nes | D191: R20
A192: 699 | B192: India | C192: IN | D192: IND
A193: 702 | B193: Singapore | C193: SG | D193: SGP
A194: 703 | B194: Slovakia | C194: SK | D194: SVK
...

Sheet Raw>>

Sheet CEPII Data
A1: k | B1: 281410
A2: t | B2: 2024
A4: Row Labels | B4: Sum of q
A5: 12 | B5: 66890227
A6: 24 | B6: 594
A7: 32 | B7: 558834
A8: 36 | B8: 244111412
A9: 40 | B9: 3352763
A10: 48 | B10: 15837538
A11: 50 | B11: 896464
A12: 56 | B12: 80926336
A13: 76 | B13: 240
A14: 100 | B14: 57268331
A15: 116 | B15: 213
A16: 124 | B16: 1081034591
... A92: 894 | B92: 3
A93: Grand Total | B93: 8800243189

Sheet Country Codes
A1: country_code,country_name,country_iso2,country_iso3
A2: 4,Afghanistan,AF,AFG
A3: 8,Albania,AL,ALB
A4: 12,Algeria,DZ,DZA
A5: 16,American Samoa,AS,ASM
A6: 20,Andorra,AD,AND
A7: 24,Angola,AO,AGO
A8: 28,Antigua and Barbuda,AG,ATG
A9: 31,Azerbaijan,AZ,AZE
A10: 32,Argentina,AR,ARG
A11: 36,Australia,AU,AUS
A12: 40,Austria,AT,AUT
... A239: 894,Zambia,ZM,ZMB
