Workbook

Sheet Output>>

Sheet Output
B2: CIP - Competitive Industrial Performance
B4: Approach: | C4: Xlookup the countries from the database - if not found, then manually add name. When more than one country, average the score. Values not found were marked in yellow and values approximated on comparable countries.
B6: ISO | C6: Country | D6: Total | F6: Helper 1 | G6: Helper 2 | H6: Helper 3 | J6: Country Helper 1 | K6: Country Helper 2 | L6: Country Helper 3
B7: NLD | C7: Netherlands | D7: =_xlfn.XLOOKUP(C7,Data!$B$2:$B$154,Data!$F$2:$F$154,"N/A",0,1) -> 0.24181235
B8: NOR | C8: Norway | D8: =_xlfn.XLOOKUP(C8,Data!$B$2:$B$154,Data!$F$2:$F$154,"N/A",0,1) -> 0.074392513
B9: SWE | C9: Sweden | D9: =_xlfn.XLOOKUP(C9,Data!$B$2:$B$154,Data!$F$2:$F$154,"N/A",0,1) -> 0.18126004
B10: ESP | C10: Spain | D10: =_xlfn.XLOOKUP(C10,Data!$B$2:$B$154,Data!$F$2:$F$154,"N/A",0,1) -> 0.15588686
B11: USA | C11: United States | D11: =_xlfn.XLOOKUP(C11,Data!$B$2:$B$154,Data!$F$2:$F$154,"N/A",0,1) -> 0.31647164
B12: JPN | C12: Japan | D12: =_xlfn.XLOOKUP(C12,Data!$B$2:$B$154,Data!$F$2:$F$154,"N/A",0,1) -> 0.30083659
B13: CHE | C13: Switzerland | D13: =_xlfn.XLOOKUP(C13,Data!$B$2:$B$154,Data!$F$2:$F$154,"N/A",0,1) -> 0.30515662
B14: DEU | C14: Germany | D14: =_xlfn.XLOOKUP(C14,Data!$B$2:$B$154,Data!$F$2:$F$154,"N/A",0,1) -> 0.41643258
B15: GBR | C15: United Kingdom | D15: =_xlfn.XLOOKUP(C15,Data!$B$2:$B$154,Data!$F$2:$F$154,"N/A",0,1) -> 0.16894739
B16: DNK | C16: Denmark | D16: =_xlfn.XLOOKUP(C16,Data!$B$2:$B$154,Data!$F$2:$F$154,"N/A",0,1) -> 0.17228965
B17: AUT | C17: Austria | D17: =_xlfn.XLOOKUP(C17,Data!$B$2:$B$154,Data!$F$2:$F$154,"N/A",0,1) -> 0.19599245
B18: CHN | C18: China | D18: =_xlfn.XLOOKUP(C18,Data!$B$2:$B$154,Data!$F$2:$F$154,"N/A",0,1) -> 0.38448559
... B41: LBN | C41: Lebanon | D41: =_xlfn.XLOOKUP(C41,Data!$B$2:$B$154,Data!$F$2:$F$154,"N/A",0,1) -> 0.012420484
B42: MRT | C42: Mauritania | D42: =D51 -> 0.046077722
B43: SAU | C43: Saudi Arabia | D43: =_xlfn.XLOOKUP(C43,Data!$B$2:$B$154,Data!$F$2:$F$154,"N/A",0,1) -> 0.072608581
B44: COK | C44: Cook Islands | D44: =D107 -> 0.0031644778
B45: ZAF | C45: South Africa | D45: =_xlfn.XLOOKUP(C45,Data!$B$2:$B$154,Data!$F$2:$F$154,"N/A",0,1) -> 0.051602221
B46: ARE | C46: United Arab Emirates | D46: =_xlfn.XLOOKUP(C46,Data!$B$2:$B$154,Data!$F$2:$F$154,"N/A",0,1) -> 0.12273672
B47: OMN | C47: Oman | D47: =_xlfn.XLOOKUP(C47,Data!$B$2:$B$154,Data!$F$2:$F$154,"N/A",0,1) -> 0.044713152
B48: URY | C48: Uruguay | D48: =_xlfn.XLOOKUP(C48,Data!$B$2:$B$154,Data!$F$2:$F$154,"N/A",0,1) -> 0.024997427
B49: PRY | C49: Paraguay | D49: =_xlfn.XLOOKUP(C49,Data!$B$2:$B$154,Data!$F$2:$F$154,"N/A",0,1) -> 0.019856116
B50: KOR | C50: Korea | D50: =_xlfn.XLOOKUP(C50,Data!$B$2:$B$154,Data!$F$2:$F$154,"N/A",0,1) -> 0.32981853
B51: MAR | C51: Morocco | D51: =_xlfn.XLOOKUP(C51,Data!$B$2:$B$154,Data!$F$2:$F$154,"N/A",0,1) -> 0.046077722
B52: ALB | C52: Albania | D52: =_xlfn.XLOOKUP(C52,Data!$B$2:$B$154,Data!$F$2:$F$154,"N/A",0,1) -> 0.011369798
B53: IDN | C53: Indonesia | D53: =_xlfn.XLOOKUP(C53,Data!$B$2:$B$154,Data!$F$2:$F$154,"N/A",0,1) -> 0.083665199
B54: BRB | C54: Barbados | D54: =_xlfn.XLOOKUP(C54,Data!$B$2:$B$154,Data!$F$2:$F$154,"N/A",0,1) -> 0.0086473789
B55: TTO | C55: Trinidad and Tobago | D55: =_xlfn.XLOOKUP(C55,Data!$B$2:$B$154,Data!$F$2:$F$154,"N/A",0,1) -> 0.03556087
B56: BGD | C56: Bangladesh | D56: =_xlfn.XLOOKUP(C56,Data!$B$2:$B$154,Data!$F$2:$F$154,"N/A",0,1) -> 0.040722481
... B85: UKR | C85: Ukraine | D85: =_xlfn.XLOOKUP(C85,Data!$B$2:$B$154,Data!$F$2:$F$154,"N/A",0,1) -> 0.022146755
B86: DJI | C86: Djibouti | D86: =D47 -> 0.044713152
B87: UZB | C87: Uzbekistan | D87: =_xlfn.XLOOKUP(C87,Data!$B$2:$B$154,Data!$F$2:$F$154,"N/A",0,1) -> 0.021465707
B88: PAN | C88: Panama | D88: =_xlfn.XLOOKUP(C88,Data!$B$2:$B$154,Data!$F$2:$F$154,"N/A",0,1) -> 0.0148698
B89: MNG | C89: Mongolia | D89: =_xlfn.XLOOKUP(C89,Data!$B$2:$B$154,Data!$F$2:$F$154,"N/A",0,1) -> 0.011446597
B90: DMA | C90: Dominica | D90: =D107 -> 0.0031644778
B91: JOR | C91: Jordan | D91: =_xlfn.XLOOKUP(C91,Data!$B$2:$B$154,Data!$F$2:$F$154,"N/A",0,1) -> 0.028284101
B92: MOZ | C92: Mozambique | D92: =_xlfn.XLOOKUP(C92,Data!$B$2:$B$154,Data!$F$2:$F$154,"N/A",0,1) -> 0.0041148509
B93: DOM | C93: Dominican Republic | D93: =D107 -> 0.0031644778
...

Sheet Raw>>

Sheet Data
A1: Year | B1: Country | C1: CountryCode | D1: Variable | E1: VariableCode | F1: Value | G1: UnitType | H1: Metadata
A2: 2023 | B2: Afghanistan | C2: 004 | D2: CIP score | E2: cip | F2: 0.00081484123 | G2: I
A3: 2023 | B3: Albania | C3: 008 | D3: CIP score | E3: cip | F3: 0.011369798 | G3: I
A4: 2023 | B4: Algeria | C4: 012 | D4: CIP score | E4: cip | F4: 0.019831627 | G4: I
A5: 2023 | B5: Angola | C5: 024 | D5: CIP score | E5: cip | F5: 0.0057435519 | G5: I
A6: 2023 | B6: Argentina | C6: 032 | D6: CIP score | E6: cip | F6: 0.048993963 | G6: I
A7: 2023 | B7: Armenia | C7: 051 | D7: CIP score | E7: cip | F7: 0.019344639 | G7: I
A8: 2023 | B8: Australia | C8: 036 | D8: CIP score | E8: cip | F8: 0.093662506 | G8: I
A9: 2023 | B9: Austria | C9: 040 | D9: CIP score | E9: cip | F9: 0.19599245 | G9: I
A10: 2023 | B10: Azerbaijan | C10: 031 | D10: CIP score | E10: cip | F10: 0.011971212 | G10: I
A11: 2023 | B11: Bahamas | C11: 044 | D11: CIP score | E11: cip | F11: 0.0029165819 | G11: I
A12: 2023 | B12: Bahrain | C12: 048 | D12: CIP score | E12: cip | F12: 0.0392959 | G12: I
A13: 2023 | B13: Bangladesh | C13: 050 | D13: CIP score | E13: cip | F13: 0.040722481 | G13: I
... A154: 2023 | B154: Zimbabwe | C154: 716 | D154: CIP score | E154: cip | F154: 0.0075752215 | G154: I

Sheet ValueType
A1: Code | B1: Description
A2: N | B2: numeric
A3: M | B3: monetary (local currency)
A4: USD | B4: $ (USD)
A5: I | B5: index
