Workbook

Sheet Output>>

Sheet Output
B2: Template
B4: Approach: | C4: Xlookup the countries from the database - if not found, then manually add name. When more than one country, average the score. Cook Islands were set to level of St. Lucia.
B6: ISO | C6: Country | D6: Total | F6: Helper 1 | G6: Helper 2 | H6: Helper 3 | J6: Country Helper 1 | K6: Country Helper 2 | L6: Country Helper 3
B7: NLD | C7: Netherlands | D7: =_xlfn.XLOOKUP(C7,Ed_CCR!$C$2:$C$146,Ed_CCR!$D$2:$D$146,"N/A",0,1) -> 0.94748455
B8: NOR | C8: Norway | D8: =_xlfn.XLOOKUP(C8,Ed_CCR!$C$2:$C$146,Ed_CCR!$D$2:$D$146,"N/A",0,1) -> 0.7417068
B9: SWE | C9: Sweden | D9: =_xlfn.XLOOKUP(C9,Ed_CCR!$C$2:$C$146,Ed_CCR!$D$2:$D$146,"N/A",0,1) -> 1.2342117
B10: ESP | C10: Spain | D10: =_xlfn.XLOOKUP(C10,Ed_CCR!$C$2:$C$146,Ed_CCR!$D$2:$D$146,"N/A",0,1) -> 0.8229609
B11: USA | C11: United States | D11: =_xlfn.XLOOKUP(C11,Ed_CCR!$C$2:$C$146,Ed_CCR!$D$2:$D$146,"N/A",0,1) -> 1.1067898
B12: JPN | C12: Japan | D12: =_xlfn.XLOOKUP(C12,Ed_CCR!$C$2:$C$146,Ed_CCR!$D$2:$D$146,"N/A",0,1) -> 1.6889353
B13: CHE | C13: Switzerland | D13: =_xlfn.XLOOKUP(C13,Ed_CCR!$C$2:$C$146,Ed_CCR!$D$2:$D$146,"N/A",0,1) -> 1.5791347
B14: DEU | C14: Germany | D14: =_xlfn.XLOOKUP(C14,Ed_CCR!$C$2:$C$146,Ed_CCR!$D$2:$D$146,"N/A",0,1) -> 1.3551035
B15: GBR | C15: United Kingdom | D15: =_xlfn.XLOOKUP(C15,Ed_CCR!$C$2:$C$146,Ed_CCR!$D$2:$D$146,"N/A",0,1) -> 1.2450106
B16: DNK | C16: Denmark | D16: =_xlfn.XLOOKUP(C16,Ed_CCR!$C$2:$C$146,Ed_CCR!$D$2:$D$146,"N/A",0,1) -> 1.0182459
B17: AUT | C17: Austria | D17: =_xlfn.XLOOKUP(C17,Ed_CCR!$C$2:$C$146,Ed_CCR!$D$2:$D$146,"N/A",0,1) -> 1.2525077
B18: CHN | C18: China | D18: =_xlfn.XLOOKUP(C18,Ed_CCR!$C$2:$C$146,Ed_CCR!$D$2:$D$146,"N/A",0,1) -> 1.2594001
... B33: GRC | C33: Greece | D33: =_xlfn.XLOOKUP(C33,Ed_CCR!$C$2:$C$146,Ed_CCR!$D$2:$D$146,"N/A",0,1) -> 0.52144676
B34: ISL | C34: Iceland | D34: =D16 -> 1.0182459
B35: TUR | C35: Türkiye | D35: =_xlfn.XLOOKUP(C35,Ed_CCR!$C$2:$C$146,Ed_CCR!$D$2:$D$146,"N/A",0,1) -> 0.70451224
B36: ARG | C36: Argentina | D36: =_xlfn.XLOOKUP(C36,Ed_CCR!$C$2:$C$146,Ed_CCR!$D$2:$D$146,"N/A",0,1) -> -0.013300096
B37: IRN | C37: Islamic Republic of Iran | D37: =_xlfn.XLOOKUP(C37,Ed_CCR!$C$2:$C$146,Ed_CCR!$D$2:$D$146,"N/A",0,1) -> -0.06532932
B38: NZL | C38: New Zealand | D38: =_xlfn.XLOOKUP(C38,Ed_CCR!$C$2:$C$146,Ed_CCR!$D$2:$D$146,"N/A",0,1) -> 0.51546836
B39: BOL | C39: Bolivia | D39: =_xlfn.XLOOKUP(C39,Ed_CCR!$C$2:$C$146,Ed_CCR!$D$2:$D$146,"N/A",0,1) -> -1.0967224
B40: PRT | C40: Portugal | D40: =_xlfn.XLOOKUP(C40,Ed_CCR!$C$2:$C$146,Ed_CCR!$D$2:$D$146,"N/A",0,1) -> 0.72070694
B41: LBN | C41: Lebanon | D41: =_xlfn.XLOOKUP(C41,Ed_CCR!$C$2:$C$146,Ed_CCR!$D$2:$D$146,"N/A",0,1) -> 0.39053303
B42: MRT | C42: Mauritania | D42: =_xlfn.XLOOKUP(C42,Ed_CCR!$C$2:$C$146,Ed_CCR!$D$2:$D$146,"N/A",0,1) -> -1.2665231
B43: SAU | C43: Saudi Arabia | D43: =_xlfn.XLOOKUP(C43,Ed_CCR!$C$2:$C$146,Ed_CCR!$D$2:$D$146,"N/A",0,1) -> 0.49866855
B44: COK | C44: Cook Islands | D44: =$D$55 -> 0.04897837
B45: ZAF | C45: South Africa | D45: =_xlfn.XLOOKUP(C45,Ed_CCR!$C$2:$C$146,Ed_CCR!$D$2:$D$146,"N/A",0,1) -> 0.36877212
B46: ARE | C46: United Arab Emirates | D46: =_xlfn.XLOOKUP(C46,Ed_CCR!$C$2:$C$146,Ed_CCR!$D$2:$D$146,"N/A",0,1) -> 0.3694089
B47: OMN | C47: Oman | D47: =_xlfn.XLOOKUP(C47,Ed_CCR!$C$2:$C$146,Ed_CCR!$D$2:$D$146,"N/A",0,1) -> -0.53910685
B48: URY | C48: Uruguay | D48: =_xlfn.XLOOKUP(C48,Ed_CCR!$C$2:$C$146,Ed_CCR!$D$2:$D$146,"N/A",0,1) -> 0.16487212
B49: PRY | C49: Paraguay | D49: =_xlfn.XLOOKUP(C49,Ed_CCR!$C$2:$C$146,Ed_CCR!$D$2:$D$146,"N/A",0,1) -> -0.23993662
B50: KOR | C50: Korea | D50: =_xlfn.XLOOKUP(C50,Ed_CCR!$C$2:$C$146,Ed_CCR!$D$2:$D$146,"N/A",0,1) -> 1.5620726
B51: MAR | C51: Morocco | D51: =_xlfn.XLOOKUP(C51,Ed_CCR!$C$2:$C$146,Ed_CCR!$D$2:$D$146,"N/A",0,1) -> -0.064083286
B52: ALB | C52: Albania | D52: =_xlfn.XLOOKUP(C52,Ed_CCR!$C$2:$C$146,Ed_CCR!$D$2:$D$146,"N/A",0,1) -> 0.04684949
B53: IDN | C53: Indonesia | D53: =_xlfn.XLOOKUP(C53,Ed_CCR!$C$2:$C$146,Ed_CCR!$D$2:$D$146,"N/A",0,1) -> 0.23433408
B54: BRB | C54: Barbados | D54: =$D$55 -> 0.04897837
B55: TTO | C55: Trinidad and Tobago | D55: =_xlfn.XLOOKUP(C55,Ed_CCR!$C$2:$C$146,Ed_CCR!$D$2:$D$146,"N/A",0,1) -> 0.04897837
B56: BGD | C56: Bangladesh | D56: =_xlfn.XLOOKUP(C56,Ed_CCR!$C$2:$C$146,Ed_CCR!$D$2:$D$146,"N/A",0,1) -> -0.44372585
B57: BRA | C57: Brazil | D57: =_xlfn.XLOOKUP(C57,Ed_CCR!$C$2:$C$146,Ed_CCR!$D$2:$D$146,"N/A",0,1) -> 0.36996418
...

Sheet Transformed>>

Sheet Ed_CCR
A1: ECI Rank | B1: Year | C1: Country | D1: ECI | E1: Change Over 5 Years
A2: 1 | B2: 2024 | C2: Japan | D2: 1.6889353 | E2: 0
A3: 2 | B3: 2024 | C3: Switzerland | D3: 1.5791347 | E3: 1
A4: 3 | B4: 2024 | C4: Chinese Taipei | D4: 1.5736563 | E4: 1
A5: 4 | B5: 2024 | C5: Korea | D5: 1.5620726 | E5: -2
A6: 5 | B6: 2024 | C6: Singapore | D6: 1.4509376 | E6: 0
A7: 6 | B7: 2024 | C7: Germany | D7: 1.3551035 | E7: 0
A8: 7 | B8: 2024 | C8: Czech Republic | D8: 1.3334634 | E8: 0
A9: 8 | B9: 2024 | C9: Israel | D9: 1.3201844 | E9: 11
A10: 9 | B10: 2024 | C10: Slovenia | D10: 1.2816952 | E10: 1
A11: 10 | B11: 2024 | C11: China | D11: 1.2594001 | E11: 3
A12: 11 | B12: 2024 | C12: Austria | D12: 1.2525077 | E12: -2
A13: 12 | B13: 2024 | C13: United Kingdom | D13: 1.2450106 | E13: 0
... A146: 145 | B146: 2024 | C146: Chad | D146: -3.5245292 | E146: -9

Sheet Raw>>

Sheet Country Complexity Rankings 202
A1: ECI Rank,"Year","Country","ECI","Change Over 5 Years"
A2: 1,"2024","Japan","1.6889353","0"
A3: 2,"2024","Switzerland","1.5791347","1"
A4: 3,"2024","Taiwan","1.5736563","1"
A5: 4,"2024","South Korea","1.5620726","-2"
A6: 5,"2024","Singapore","1.4509376","0"
A7: 6,"2024","Germany","1.3551035","0"
A8: 7,"2024","Czechia","1.3334634","0"
A9: 8,"2024","Israel","1.3201844","11"
A10: 9,"2024","Slovenia","1.2816952","1"
A11: 10,"2024","China","1.2594001","3"
A12: 11,"2024","Austria","1.2525077","-2"
... A146: 145,"2024","Chad","-3.5245292","-9"
