Workbook

Sheet Output
B2: Ease of doing business per country
B4: Approach: | C4: Xlookup the countries from the database - if not found, then manually add name. When more than one country, average the score. Cook Islands were set to level of St. Lucia.
B6: ISO | C6: Country | D6: Value | F6: Helper 1 | G6: Helper 2 | H6: Helper 3 | J6: Country Helper 1 | K6: Country Helper 2 | L6: Country Helper 3
B7: NLD | C7: Netherlands | D7: =IFERROR(_xlfn.XLOOKUP(C7,'Ease of Doing Business'!$B$11:$B$223,'Ease of Doing Business'!$D$11:$D$223,"N/A",0,1),AVERAGE(F7:H7)) -> 76.1
B8: NOR | C8: Norway | D8: =IFERROR(_xlfn.XLOOKUP(C8,'Ease of Doing Business'!$B$11:$B$223,'Ease of Doing Business'!$D$11:$D$223,"N/A",0,1),AVERAGE(F8:H8)) -> 82.6
B9: SWE | C9: Sweden | D9: =IFERROR(_xlfn.XLOOKUP(C9,'Ease of Doing Business'!$B$11:$B$223,'Ease of Doing Business'!$D$11:$D$223,"N/A",0,1),AVERAGE(F9:H9)) -> 82
B10: ESP | C10: Spain | D10: =IFERROR(_xlfn.XLOOKUP(C10,'Ease of Doing Business'!$B$11:$B$223,'Ease of Doing Business'!$D$11:$D$223,"N/A",0,1),AVERAGE(F10:H10)) -> 77.9
B11: USA | C11: United States | D11: =IFERROR(_xlfn.XLOOKUP(C11,'Ease of Doing Business'!$B$11:$B$223,'Ease of Doing Business'!$D$11:$D$223,"N/A",0,1),AVERAGE(F11:H11)) -> 84
B12: JPN | C12: Japan | D12: =IFERROR(_xlfn.XLOOKUP(C12,'Ease of Doing Business'!$B$11:$B$223,'Ease of Doing Business'!$D$11:$D$223,"N/A",0,1),AVERAGE(F12:H12)) -> 78
B13: CHE | C13: Switzerland | D13: =IFERROR(_xlfn.XLOOKUP(C13,'Ease of Doing Business'!$B$11:$B$223,'Ease of Doing Business'!$D$11:$D$223,"N/A",0,1),AVERAGE(F13:H13)) -> 76.6
B14: DEU | C14: Germany | D14: =IFERROR(_xlfn.XLOOKUP(C14,'Ease of Doing Business'!$B$11:$B$223,'Ease of Doing Business'!$D$11:$D$223,"N/A",0,1),AVERAGE(F14:H14)) -> 79.7
B15: GBR | C15: United Kingdom | D15: =IFERROR(_xlfn.XLOOKUP(C15,'Ease of Doing Business'!$B$11:$B$223,'Ease of Doing Business'!$D$11:$D$223,"N/A",0,1),AVERAGE(F15:H15)) -> 83.5
B16: DNK | C16: Denmark | D16: =IFERROR(_xlfn.XLOOKUP(C16,'Ease of Doing Business'!$B$11:$B$223,'Ease of Doing Business'!$D$11:$D$223,"N/A",0,1),AVERAGE(F16:H16)) -> 85.3
B17: AUT | C17: Austria | D17: =IFERROR(_xlfn.XLOOKUP(C17,'Ease of Doing Business'!$B$11:$B$223,'Ease of Doing Business'!$D$11:$D$223,"N/A",0,1),AVERAGE(F17:H17)) -> 78.7
B18: CHN | C18: China | D18: =IFERROR(_xlfn.XLOOKUP(C18,'Ease of Doing Business'!$B$11:$B$223,'Ease of Doing Business'!$D$11:$D$223,"N/A",0,1),AVERAGE(F18:H18)) -> 77.9
... B42: MRT | C42: Mauritania | D42: =IFERROR(_xlfn.XLOOKUP(C42,'Ease of Doing Business'!$B$11:$B$223,'Ease of Doing Business'!$D$11:$D$223,"N/A",0,1),AVERAGE(F42:H42)) -> 51.1
B43: PRT ESP | C43: #N/A | D43: =IFERROR(_xlfn.XLOOKUP(C43,'Ease of Doing Business'!$B$11:$B$223,'Ease of Doing Business'!$D$11:$D$223,"N/A",0,1),AVERAGE(F43:H43)) -> 77.2 | F43: =_xlfn.XLOOKUP(J43,$B$7:$B$112,$D$7:$D$112) -> 76.5 | G43: =_xlfn.XLOOKUP(K43,$B$7:$B$112,$D$7:$D$112) -> 77.9 | J43: PRT | K43: ESP
B44: SAU | C44: Saudi Arabia | D44: =IFERROR(_xlfn.XLOOKUP(C44,'Ease of Doing Business'!$B$11:$B$223,'Ease of Doing Business'!$D$11:$D$223,"N/A",0,1),AVERAGE(F44:H44)) -> 71.6
B45: ROM DEU AUT | C45: #N/A | D45: =IFERROR(_xlfn.XLOOKUP(C45,'Ease of Doing Business'!$B$11:$B$223,'Ease of Doing Business'!$D$11:$D$223,"N/A",0,1),AVERAGE(F45:H45)) -> 79.2 | G45: =_xlfn.XLOOKUP(K45,$B$7:$B$112,$D$7:$D$112) -> 79.7 | H45: =_xlfn.XLOOKUP(L45,$B$7:$B$112,$D$7:$D$112) -> 78.7 | J45: ROM | K45: DEU | L45: AUT
B46: POL CZE SVK HUN | C46: #N/A | D46: =IFERROR(_xlfn.XLOOKUP(C46,'Ease of Doing Business'!$B$11:$B$223,'Ease of Doing Business'!$D$11:$D$223,"N/A",0,1),AVERAGE(F46:H46)) -> 76.1 | F46: =_xlfn.XLOOKUP(J46,$B$7:$B$112,$D$7:$D$112) -> 76.4 | G46: =_xlfn.XLOOKUP(K46,$B$7:$B$112,$D$7:$D$112) -> 76.3 | H46: =_xlfn.XLOOKUP(L46,$B$7:$B$112,$D$7:$D$112) -> 75.6 | J46: POL | K46: CZE | L46: SVK
B47: COK | C47: Cook Islands | D47: =D112 -> 63.7
B48: ZAF | C48: South Africa | D48: =IFERROR(_xlfn.XLOOKUP(C48,'Ease of Doing Business'!$B$11:$B$223,'Ease of Doing Business'!$D$11:$D$223,"N/A",0,1),AVERAGE(F48:H48)) -> 67
B49: ARE | C49: United Arab Emirates | D49: =IFERROR(_xlfn.XLOOKUP(C49,'Ease of Doing Business'!$B$11:$B$223,'Ease of Doing Business'!$D$11:$D$223,"N/A",0,1),AVERAGE(F49:H49)) -> 80.9
B50: OMN | C50: Oman | D50: =IFERROR(_xlfn.XLOOKUP(C50,'Ease of Doing Business'!$B$11:$B$223,'Ease of Doing Business'!$D$11:$D$223,"N/A",0,1),AVERAGE(F50:H50)) -> 70
B51: URY | C51: Uruguay | D51: =IFERROR(_xlfn.XLOOKUP(C51,'Ease of Doing Business'!$B$11:$B$223,'Ease of Doing Business'!$D$11:$D$223,"N/A",0,1),AVERAGE(F51:H51)) -> 61.5
B52: PRY | C52: Paraguay | D52: =IFERROR(_xlfn.XLOOKUP(C52,'Ease of Doing Business'!$B$11:$B$223,'Ease of Doing Business'!$D$11:$D$223,"N/A",0,1),AVERAGE(F52:H52)) -> 59.1
B53: ESP FRA | C53: #N/A | D53: =IFERROR(_xlfn.XLOOKUP(C53,'Ease of Doing Business'!$B$11:$B$223,'Ease of Doing Business'!$D$11:$D$223,"N/A",0,1),AVERAGE(F53:H53)) -> 77.35 | F53: =_xlfn.XLOOKUP(J53,$B$7:$B$112,$D$7:$D$112) -> 77.9 | G53: =_xlfn.XLOOKUP(K53,$B$7:$B$112,$D$7:$D$112) -> 76.8 | J53: ESP | K53: FRA
B54: KOR | C54: Korea | D54: =IFERROR(_xlfn.XLOOKUP(C54,'Ease of Doing Business'!$B$11:$B$223,'Ease of Doing Business'!$D$11:$D$223,"N/A",0,1),AVERAGE(F54:H54)) -> 84
B55: MAR | C55: Morocco | D55: =IFERROR(_xlfn.XLOOKUP(C55,'Ease of Doing Business'!$B$11:$B$223,'Ease of Doing Business'!$D$11:$D$223,"N/A",0,1),AVERAGE(F55:H55)) -> 73.4
B56: ALB | C56: Albania | D56: =IFERROR(_xlfn.XLOOKUP(C56,'Ease of Doing Business'!$B$11:$B$223,'Ease of Doing Business'!$D$11:$D$223,"N/A",0,1),AVERAGE(F56:H56)) -> 67.7
B57: IDN | C57: Indonesia | D57: =IFERROR(_xlfn.XLOOKUP(C57,'Ease of Doing Business'!$B$11:$B$223,'Ease of Doing Business'!$D$11:$D$223,"N/A",0,1),AVERAGE(F57:H57)) -> 69.6
B58: BRB | C58: Barbados | D58: =IFERROR(_xlfn.XLOOKUP(C58,'Ease of Doing Business'!$B$11:$B$223,'Ease of Doing Business'!$D$11:$D$223,"N/A",0,1),AVERAGE(F58:H58)) -> 57.9
B59: TTO | C59: Trinidad and Tobago | D59: =IFERROR(_xlfn.XLOOKUP(C59,'Ease of Doing Business'!$B$11:$B$223,'Ease of Doing Business'!$D$11:$D$223,"N/A",0,1),AVERAGE(F59:H59)) -> 61.3
B60: BGD | C60: Bangladesh | D60: =IFERROR(_xlfn.XLOOKUP(C60,'Ease of Doing Business'!$B$11:$B$223,'Ease of Doing Business'!$D$11:$D$223,"N/A",0,1),AVERAGE(F60:H60)) -> 45
B61: BRA | C61: Brazil | D61: =IFERROR(_xlfn.XLOOKUP(C61,'Ease of Doing Business'!$B$11:$B$223,'Ease of Doing Business'!$D$11:$D$223,"N/A",0,1),AVERAGE(F61:H61)) -> 59.1
B62: HUN | C62: Hungary | D62: =IFERROR(_xlfn.XLOOKUP(C62,'Ease of Doing Business'!$B$11:$B$223,'Ease of Doing Business'!$D$11:$D$223,"N/A",0,1),AVERAGE(F62:H62)) -> 73.4
B63: TWN | C63: Chinese Taipei | D63: =IFERROR(_xlfn.XLOOKUP(C63,'Ease of Doing Business'!$B$11:$B$223,'Ease of Doing Business'!$D$11:$D$223,"N/A",0,1),AVERAGE(F63:H63)) -> 80.9
B64: MEX | C64: Mexico | D64: =IFERROR(_xlfn.XLOOKUP(C64,'Ease of Doing Business'!$B$11:$B$223,'Ease of Doing Business'!$D$11:$D$223,"N/A",0,1),AVERAGE(F64:H64)) -> 72.4
B65: VNM | C65: Viet Nam | D65: =IFERROR(_xlfn.XLOOKUP(C65,'Ease of Doing Business'!$B$11:$B$223,'Ease of Doing Business'!$D$11:$D$223,"N/A",0,1),AVERAGE(F65:H65)) -> 69.8
... B68: SVK | C68: Slovak Republic | D68: =IFERROR(_xlfn.XLOOKUP(C68,'Ease of Doing Business'!$B$11:$B$223,'Ease of Doing Business'!$D$11:$D$223,"N/A",0,1),AVERAGE(F68:H68)) -> 75.6
...

Sheet Raw>>

Sheet Ease of Doing Business
B1: Economy | C1: DB 2019 | D1: DB 2020
A2: Region
B3: East Asia & Pacific | C3: 62.7 | D3: 63.3
B4: Europe & Central Asia | C4: 71.8 | D4: 73.1
B5: Latin America & Caribbean | C5: 58.8 | D5: 59.1
B6: Middle East & North Africa | C6: 58.4 | D6: 60.2
B7: OECD high income | C7: 78.2 | D7: 78.4
B8: South Asia | C8: 56.3 | D8: 58.2
B9: Sub-Saharan Africa | C9: 50.9 | D9: 51.8
A10: Economy
B11: Afghanistan | C11: 44.2 | D11: 44.1
B12: Albania | C12: 67 | D12: 67.7
B13: Algeria | C13: 48.5 | D13: 48.6
B14: Angola | C14: 41.2 | D14: 41.3
B15: Antigua and Barbuda | C15: 59.9 | D15: 60.3
B16: Argentina | C16: 58.2 | D16: 59
B17: Armenia | C17: 73.2 | D17: 74.5
B18: Australia | C18: 80.7 | D18: 81.2
B19: Austria | C19: 78.7 | D19: 78.7
B20: Azerbaijan | C20: 73.6 | D20: 76.7
B21: Bahamas, The | C21: 59.4 | D21: 59.9
B22: Bahrain | C22: 70.1 | D22: 76
... B223: Zimbabwe | C223: 50.5 | D223: 54.5
