Workbook

Sheet Output>>

Sheet Output
B2: Freshwater withdrawal as a proportion of available freshwater resources
B4: Approach: | C4: Xlookup the countries from the database - if not found, then manually add name. When more than one country, average the score. Cook Islands were set to level of St. Lucia. For Israel, 2021 values were used
B6: ISO | C6: Country | D6: Total | F6: Helper 1 | G6: Helper 2 | H6: Helper 3 | J6: Country Helper 1 | K6: Country Helper 2 | L6: Country Helper 3
B7: NLD | C7: Netherlands | D7: =_xlfn.XLOOKUP(B7,ED_Freshwater!$E$2:$E$179,ED_Freshwater!$CX$2:$CX$179,"N/A",0,1) -> 16.658507
B8: NOR | C8: Norway | D8: =_xlfn.XLOOKUP(B8,ED_Freshwater!$E$2:$E$179,ED_Freshwater!$CX$2:$CX$179,"N/A",0,1) -> 2.0440076
B9: SWE | C9: Sweden | D9: =_xlfn.XLOOKUP(B9,ED_Freshwater!$E$2:$E$179,ED_Freshwater!$CX$2:$CX$179,"N/A",0,1) -> 3.5829726
B10: ESP | C10: Spain | D10: =_xlfn.XLOOKUP(B10,ED_Freshwater!$E$2:$E$179,ED_Freshwater!$CX$2:$CX$179,"N/A",0,1) -> 43.254039
B11: USA | C11: United States | D11: =_xlfn.XLOOKUP(B11,ED_Freshwater!$E$2:$E$179,ED_Freshwater!$CX$2:$CX$179,"N/A",0,1) -> 28.15526
B12: JPN | C12: Japan | D12: =_xlfn.XLOOKUP(B12,ED_Freshwater!$E$2:$E$179,ED_Freshwater!$CX$2:$CX$179,"N/A",0,1) -> 36.643678
B13: CHE | C13: Switzerland | D13: =_xlfn.XLOOKUP(B13,ED_Freshwater!$E$2:$E$179,ED_Freshwater!$CX$2:$CX$179,"N/A",0,1) -> 6.4988558
B14: DEU | C14: Germany | D14: =_xlfn.XLOOKUP(B14,ED_Freshwater!$E$2:$E$179,ED_Freshwater!$CX$2:$CX$179,"N/A",0,1) -> 35.351657
B15: GBR | C15: United Kingdom | D15: =_xlfn.XLOOKUP(B15,ED_Freshwater!$E$2:$E$179,ED_Freshwater!$CX$2:$CX$179,"N/A",0,1) -> 14.354646
B16: DNK | C16: Denmark | D16: =_xlfn.XLOOKUP(B16,ED_Freshwater!$E$2:$E$179,ED_Freshwater!$CX$2:$CX$179,"N/A",0,1) -> 25.26636
B17: AUT | C17: Austria | D17: =_xlfn.XLOOKUP(B17,ED_Freshwater!$E$2:$E$179,ED_Freshwater!$CX$2:$CX$179,"N/A",0,1) -> 8.67643
B18: CHN | C18: China | D18: =_xlfn.XLOOKUP(B18,ED_Freshwater!$E$2:$E$179,ED_Freshwater!$CX$2:$CX$179,"N/A",0,1) -> 41.518529
... B43: SAU | C43: Saudi Arabia | D43: =_xlfn.XLOOKUP(B43,ED_Freshwater!$E$2:$E$179,ED_Freshwater!$CX$2:$CX$179,"N/A",0,1) -> 974.16667
B44: COK | C44: Cook Islands | D44: =D107 -> 14.3
B45: ZAF | C45: South Africa | D45: =_xlfn.XLOOKUP(B45,ED_Freshwater!$E$2:$E$179,ED_Freshwater!$CX$2:$CX$179,"N/A",0,1) -> 67.595261
B46: ARE | C46: United Arab Emirates | D46: =_xlfn.XLOOKUP(B46,ED_Freshwater!$E$2:$E$179,ED_Freshwater!$CX$2:$CX$179,"N/A",0,1) -> 1509.9333
B47: OMN | C47: Oman | D47: =_xlfn.XLOOKUP(B47,ED_Freshwater!$E$2:$E$179,ED_Freshwater!$CX$2:$CX$179,"N/A",0,1) -> 116.71429
B48: URY | C48: Uruguay | D48: =_xlfn.XLOOKUP(B48,ED_Freshwater!$E$2:$E$179,ED_Freshwater!$CX$2:$CX$179,"N/A",0,1) -> 12.052014
B49: PRY | C49: Paraguay | D49: =_xlfn.XLOOKUP(B49,ED_Freshwater!$E$2:$E$179,ED_Freshwater!$CX$2:$CX$179,"N/A",0,1) -> 1.8353997
B50: KOR | C50: Korea | D50: =_xlfn.XLOOKUP(B50,ED_Freshwater!$E$2:$E$179,ED_Freshwater!$CX$2:$CX$179,"N/A",0,1) -> 85.221833
B51: MAR | C51: Morocco | D51: =_xlfn.XLOOKUP(B51,ED_Freshwater!$E$2:$E$179,ED_Freshwater!$CX$2:$CX$179,"N/A",0,1) -> 50.751212
B52: ALB | C52: Albania | D52: =_xlfn.XLOOKUP(B52,ED_Freshwater!$E$2:$E$179,ED_Freshwater!$CX$2:$CX$179,"N/A",0,1) -> 4.7896635
B53: IDN | C53: Indonesia | D53: =_xlfn.XLOOKUP(B53,ED_Freshwater!$E$2:$E$179,ED_Freshwater!$CX$2:$CX$179,"N/A",0,1) -> 29.696545
B54: BRB | C54: Barbados | D54: =_xlfn.XLOOKUP(B54,ED_Freshwater!$E$2:$E$179,ED_Freshwater!$CX$2:$CX$179,"N/A",0,1) -> 87.5
B55: TTO | C55: Trinidad and Tobago | D55: =_xlfn.XLOOKUP(B55,ED_Freshwater!$E$2:$E$179,ED_Freshwater!$CX$2:$CX$179,"N/A",0,1) -> 20.326481
B56: BGD | C56: Bangladesh | D56: =_xlfn.XLOOKUP(B56,ED_Freshwater!$E$2:$E$179,ED_Freshwater!$CX$2:$CX$179,"N/A",0,1) -> 5.7233395
... B58: HUN | C58: Hungary | D58: =_xlfn.XLOOKUP(B58,ED_Freshwater!$E$2:$E$179,ED_Freshwater!$CX$2:$CX$179,"N/A",0,1) -> 8.1084974
B59: TWN | C59: Chinese Taipei | D59: =D18 -> 41.518529
B60: MEX | C60: Mexico | D60: =_xlfn.XLOOKUP(B60,ED_Freshwater!$E$2:$E$179,ED_Freshwater!$CX$2:$CX$179,"N/A",0,1) -> 44.945147
B61: VNM | C61: Viet Nam | D61: =_xlfn.XLOOKUP(B61,ED_Freshwater!$E$2:$E$179,ED_Freshwater!$CX$2:$CX$179,"N/A",0,1) -> 18.130315
B62: SVN | C62: Slovenia | D62: =_xlfn.XLOOKUP(B62,ED_Freshwater!$E$2:$E$179,ED_Freshwater!$CX$2:$CX$179,"N/A",0,1) -> 5.591616
B63: CZE | C63: Czech Republic | D63: =_xlfn.XLOOKUP(B63,ED_Freshwater!$E$2:$E$179,ED_Freshwater!$CX$2:$CX$179,"N/A",0,1) -> 21.973844
B64: SVK | C64: Slovak Republic | D64: =_xlfn.XLOOKUP(B64,ED_Freshwater!$E$2:$E$179,ED_Freshwater!$CX$2:$CX$179,"N/A",0,1) -> 2.4252303
B65: LTU | C65: Lithuania | D65: =_xlfn.XLOOKUP(B65,ED_Freshwater!$E$2:$E$179,ED_Freshwater!$CX$2:$CX$179,"N/A",0,1) -> 2.1655371
B66: LVA | C66: Latvia | D66: =_xlfn.XLOOKUP(B66,ED_Freshwater!$E$2:$E$179,ED_Freshwater!$CX$2:$CX$179,"N/A",0,1) -> 1.0155215
B67: IRL | C67: Ireland | D67: =_xlfn.XLOOKUP(B67,ED_Freshwater!$E$2:$E$179,ED_Freshwater!$CX$2:$CX$179,"N/A",0,1) -> 8.0510106
B68: PER | C68: Peru | D68: =_xlfn.XLOOKUP(B68,ED_Freshwater!$E$2:$E$179,ED_Freshwater!$CX$2:$CX$179,"N/A",0,1) -> 4.8284277
...

Sheet Edit>>

Sheet ED_Freshwater
A1: STRUCTURE | B1: STRUCTURE_ID | C1: ACTION | D1: FREQ | E1: REF_AREA | F1: INDICATOR | G1: SEX | H1: AGE | I1: URBANISATION | J1: UNIT_MEASURE | K1: COMP_BREAKDOWN_1 | L1: COMP_BREAKDOWN_2 | M1: COMP_BREAKDOWN_3 | N1: AGG_METHOD | O1: UNIT_TYPE | P1: DECIMALS | Q1: DATABASE_ID | R1: TIME_FORMAT | S1: COMMENT_TS | T1: UNIT_MULT | U1: DATA_SOURCE | V1: OBS_CONF | W1: OBS_STATUS | X1: FREQ_LABEL | Y1: REF_AREA_LABEL | Z1: INDICATOR_LABEL | AA1: SEX_LABEL | AB1: AGE_LABEL | AC1: URBANISATION_LABEL | AD1: UNIT_MEASURE_LABEL | AE1: COMP_BREAKDOWN_1_LABEL | AF1: COMP_BREAKDOWN_2_LABEL | AG1: COMP_BREAKDOWN_3_LABEL | AH1: AGG_METHOD_LABEL | AI1: UNIT_TYPE_LABEL | AJ1: DECIMALS_LABEL | AK1: DATABASE_ID_LABEL | AL1: TIME_FORMAT_LABEL | AM1: UNIT_MULT_LABEL | AN1: OBS_STATUS_LABEL | AO1: OBS_CONF_LABEL | AP1: 1962 | AQ1: 1963 | AR1: 1964 | AS1: 1965 | AT1: 1966 | AU1: 1967 | AV1: 1968 | AW1: 1969 | AX1: 1970 | AY1: 1971 | AZ1: 1972 | BA1: 1973 | BB1: 1974 | BC1: 1975 | BD1: 1976 | BE1: 1977 | BF1: 1978 | BG1: 1979 | BH1: 1980 | BI1: 1981 | BJ1: 1982 | BK1: 1983 | BL1: 1984 | BM1: 1985 | BN1: 1986 | BO1: 1987 | BP1: 1988 | BQ1: 1989 | BR1: 1990 | BS1: 1991 | BT1: 1992 | BU1: 1993 | BV1: 1994 | BW1: 1995 | BX1: 1996 | BY1: 1997 | BZ1: 1998 | CA1: 1999 | CB1: 2000 | CC1: 2001 | CD1: 2002 | CE1: 2003 | CF1: 2004 | CG1: 2005 | CH1: 2006 | CI1: 2007 | CJ1: 2008 | CK1: 2009 | CL1: 2010 | CM1: 2011 | CN1: 2012 | CO1: 2013 | CP1: 2014 | CQ1: 2015 | CR1: 2016 | CS1: 2017 | CT1: 2018 | CU1: 2019 | CV1: 2020 | CW1: 2021 | CX1: 2022 (in %)
A2: datastructure | B2: WB.DATA360:DS_DATA360(1.3) | C2: I | D2: A | E2: VNM | F2: WB_WDI_ER_H2O_FWST_ZS | G2: _T | H2: _T | I2: _T | J2: PT_FRSH_WAT_RSC | K2: _Z | L2: _Z | M2: _Z | N2: _Z | O2: RATIO | P2: 2 | Q2: WB_WDI | R2: P1Y | S2: Level of water stress: freshwater withdrawal as a proportion of available freshwater resources | T2: 0 | U2: WB_WDI | V2: PU | W2: A | X2: Annual | Y2: Vietnam | Z2: Level of water stress: freshwater withdrawal as a proportion of available freshwater resources | AA2: Total | AB2: All age ranges or no breakdown by age | AC2: Total | AD2: Percentage of freshwater resources | AE2: Not Applicable | AF2: Not Applicable | AG2: Not Applicable | AH2: Not Applicable | AI2: Ratio | AJ2: Two | AK2: World Development Indicators (WDI) | AL2: Annual | AM2: Units | AN2: Normal value | AO2: Public | BH2: 8.3850106 | BI2: 8.7132353 | BJ2: 9.04146 | BK2: 9.3696846 | BL2: 9.6979093 | BM2: 10.026134 | BN2: 10.302888 | BO2: 10.579642 | BP2: 10.856396 | BQ2: 11.13315 | BR2: 11.409904 | BS2: 11.859408 | BT2: 12.308912 | BU2: 12.758416 | BV2: 13.20792 | BW2: 13.657424 | BX2: 14.106928 | BY2: 14.556432 | BZ2: 15.005936 | CA2: 15.455439 | CB2: 15.904943 | CC2: 16.357459 | CD2: 16.809975 | CE2: 17.223733 | CF2: 17.676249 | CG2: 18.130315 | CH2: 18.130315 | CI2: 18.130315 | CJ2: 18.130315 | CK2: 18.130315 | CL2: 18.130315 | CM2: 18.130315 | CN2: 18.130315 | CO2: 18.130315 | CP2: 18.130315 | CQ2: 18.130315 | CR2: 18.130315 | CS2: 18.130315 | CT2: 18.130315 | CU2: 18.130315 | CV2: 18.130315 | CW2: 18.130315 | CX2: 18.130315
A3: datastructure | B3: WB.DATA360:DS_DATA360(1.3) | C3: I | D3: A | E3: NGA | F3: WB_WDI_ER_H2O_FWST_ZS | G3: _T | H3: _T | I3: _T | J3: PT_FRSH_WAT_RSC | K3: _Z | L3: _Z | M3: _Z | N3: _Z | O3: RATIO | P3: 2 | Q3: WB_WDI | R3: P1Y | S3: Level of water stress: freshwater withdrawal as a proportion of available freshwater resources | T3: 0 | U3: WB_WDI | V3: PU | W3: A | X3: Annual | Y3: Nigeria | Z3: Level of water stress: freshwater withdrawal as a proportion of available freshwater resources | AA3: Total | AB3: All age ranges or no breakdown by age | AC3: Total | AD3: Percentage of freshwater resources | AE3: Not Applicable | AF3: Not Applicable | AG3: Not Applicable | AH3: Not Applicable | AI3: Ratio | AJ3: Two | AK3: World Development Indicators (WDI) | AL3: Annual | AM3: Units | AN3: Normal value | AO3: Public | BO3: 4.3333333 | BP3: 4.6143709 | BQ3: 4.8957662 | BR3: 5.1746571 | BS3: 5.4558736 | BT3: 5.73709 | BU3: 6.0183065 | BV3: 6.299523 | BW3: 6.5807394 | BX3: 6.8619559 | BY3: 7.143709 | BZ3: 7.4243888 | CA3: 7.7057841 | CB3: 7.9868217 | CC3: 8.1834109 | CD3: 8.38 | CE3: 8.5765891 | CF3: 8.7731783 | CG3: 8.9697674 | CH3: 9.1094574 | CI3: 9.2491473 | CJ3: 9.3888372 | CK3: 9.5285271 | CL3: 9.6682171 | CM3: 9.6682171 | CN3: 9.6682171 | CO3: 9.6682171 | CP3: 9.6682171 | CQ3: 9.6682171 | CR3: 9.6682171 | CS3: 9.6682171 | CT3: 9.6682171 | CU3: 9.6682171 | CV3: 9.6682171 | CW3: 9.6682171 | CX3: 9.6682171
A4: datastructure | B4: WB.DATA360:DS_DATA360(1.3) | C4: I | D4: A | E4: SVN | F4: WB_WDI_ER_H2O_FWST_ZS | G4: _T | H4: _T | I4: _T | J4: PT_FRSH_WAT_RSC | K4: _Z | L4: _Z | M4: _Z | N4: _Z | O4: RATIO | P4: 2 | Q4: WB_WDI | R4: P1Y | S4: Level of water stress: freshwater withdrawal as a proportion of available freshwater resources | T4: 0 | U4: WB_WDI | V4: PU | W4: A | X4: Annual | Y4: Slovenia | Z4: Level of water stress: freshwater withdrawal as a proportion of available freshwater resources | AA4: Total | AB4: All age ranges or no breakdown by age | AC4: Total | AD4: Percentage of freshwater resources | AE4: Not Applicable | AF4: Not Applicable | AG4: Not Applicable | AH4: Not Applicable | AI4: Ratio | AJ4: Two | AK4: World Development Indicators (WDI) | AL4: Annual | AM4: Units | AN4: Normal value | AO4: Public | CD4: 6.0797836 | CE4: 6.1347757 | CF4: 6.1897679 | CG4: 6.24476 | CH4: 6.2846518 | CI4: 6.3245436 | CJ4: 7.0317782 | CK4: 6.3739013 | CL4: 6.2576065 | CM4: 5.7491548 | CN4: 6.2745098 | CO4: 7.8133874 | CP4: 6.6281271 | CQ4: 6.0649087 | CR4: 5.9993239 | CS4: 6.2974983 | CT4: 6.4976335 | CU4: 6.382691 | CV4: 6.7816092 | CW4: 6.2947938 | CX4: 5.591616
A5: datastructure | B5: WB.DATA360:DS_DATA360(1.3) | C5: I | D5: A | E5: CAN | F5: WB_WDI_ER_H2O_FWST_ZS | G5: _T | H5: _T | I5: _T | J5: PT_FRSH_WAT_RSC | K5: _Z | L5: _Z | M5: _Z | N5: _Z | O5: RATIO | P5: 2 | Q5: WB_WDI | R5: P1Y | S5: Level of water stress: freshwater withdrawal as a proportion of available freshwater resources | T5: 0 | U5: WB_WDI | V5: PU | W5: A | X5: Annual | Y5: Canada | Z5: Level of water stress: freshwater withdrawal as a proportion of available freshwater resources | AA5: Total | AB5: All age ranges or no breakdown by age | AC5: Total | AD5: Percentage of freshwater resources | AE5: Not Applicable | AF5: Not Applicable | AG5: Not Applicable | AH5: Not Applicable | AI5: Ratio | AJ5: Two | AK5: World Development Indicators (WDI) | AL5: Annual | AM5: Units | AN5: Normal value | AO5: Public | BN5: 4.346035 | BO5: 4.4055819 | BP5: 4.4651287 | BQ5: 4.5246756 | BR5: 4.5842225 | BS5: 4.6437693 | BT5: 4.584449 | BU5: 4.5251287 | BV5: 4.4658084 | BW5: 4.4064882 | BX5: 4.3471679 | BY5: 4.3388007 | BZ5: 4.3304335 | CA5: 4.3220663 | CB5: 4.3136991 | CC5: 4.3053319 | CD5: 4.2969647 | CE5: 4.2885975 | CF5: 4.2802303 | CG5: 4.2718631 | CH5: 4.2634959 | CI5: 4.2551287 | CJ5: 4.1253656 | CK5: 3.9956025 | CL5: 3.8309629 | CM5: 3.6663234 | CN5: 3.7528321 | CO5: 3.8393409 | CP5: 3.7595263 | CQ5: 3.6797116 | CR5: 3.7066426 | CS5: 3.7335736 | CT5: 3.7335736 | CU5: 3.7335736 | CV5: 3.7335736 | CW5: 3.7207003 | CX5: 3.7207003
A6: datastructure | B6: WB.DATA360:DS_DATA360(1.3) | C6: I | D6: A | E6: EST | F6: WB_WDI_ER_H2O_FWST_ZS | G6: _T | H6: _T | I6: _T | J6: PT_FRSH_WAT_RSC | K6: _Z | L6: _Z | M6: _Z | N6: _Z | O6: RATIO | P6: 2 | Q6: WB_WDI | R6: P1Y | S6: Level of water stress: freshwater withdrawal as a proportion of available freshwater resources | T6: 0 | U6: WB_WDI | V6: PU | W6: A | X6: Annual | Y6: Estonia | Z6: Level of water stress: freshwater withdrawal as a proportion of available freshwater resources | AA6: Total | AB6: All age ranges or no breakdown by age | AC6: Total | AD6: Percentage of freshwater resources | AE6: Not Applicable | AF6: Not Applicable | AG6: Not Applicable | AH6: Not Applicable | AI6: Ratio | AJ6: Two | AK6: World Development Indicators (WDI) | AL6: Annual | AM6: Units | AN6: Normal value | AO6: Public | BT6: 28.463203 | BU6: 23.874459 | BV6: 19.285714 | BW6: 14.69697 | BX6: 14.782622 | BY6: 14.868275 | BZ6: 14.953927 | CA6: 15.039579 | CB6: 15.125232 | CC6: 15.210884 | CD6: 15.296537 | CE6: 16.20671 | CF6: 17.116883 | CG6: 18.027056 | CH6: 18.937229 | CI6: 19.847403 | CJ6: 17.359307 | CK6: 14.91342 | CL6: 19.935065 | CM6: 20.281385 | CN6: 17.651515 | CO6: 18.917749 | CP6: 18.614719 | CQ6: 17.482063 | CR6: 18.954545 | CS6: 19.3171 | CT6: 17.408442 | CU6: 10.892316 | CV6: 9.2310855 | CW6: 10.819801 | CX6: 13.046285
A7: datastructure | B7: WB.DATA360:DS_DATA360(1.3) | C7: I | D7: A | E7: BFA | F7: WB_WDI_ER_H2O_FWST_ZS | G7: _T | H7: _T | I7: _T | J7: PT_FRSH_WAT_RSC | K7: _Z | L7: _Z | M7: _Z | N7: _Z | O7: RATIO | P7: 2 | Q7: WB_WDI | R7: P1Y | S7: Level of water stress: freshwater withdrawal as a proportion of available freshwater resources | T7: 0 | U7: WB_WDI | V7: PU | W7: A | X7: Annual | Y7: Burkina Faso | Z7: Level of water stress: freshwater withdrawal as a proportion of available freshwater resources | AA7: Total | AB7: All age ranges or no breakdown by age | AC7: Total | AD7: Percentage of freshwater resources | AE7: Not Applicable | AF7: Not Applicable | AG7: Not Applicable | AH7: Not Applicable | AI7: Ratio | AJ7: Two | AK7: World Development Indicators (WDI) | AL7: Annual | AM7: Units | AN7: Normal value | AO7: Public | BM7: 2.7724665 | BN7: 2.8898662 | BO7: 3.0072658 | BP7: 3.1246654 | BQ7: 3.242065 | BR7: 3.3594646 | BS7: 3.4770554 | BT7: 3.5946463 | BU7: 3.7786276 | BV7: 3.9626089 | BW7: 4.1465902 | BX7: 4.3305715 | BY7: 4.5145528 | BZ7: 5.5449331 | CA7: 5.8699809 | CB7: 6.1950287 | CC7: 6.5200765 | CD7: 6.8451243 | CE7: 7.1701721 | CF7: 7.4952199 | CG7: 7.8202677 | CH7: 7.8202677 | CI7: 7.8202677 | CJ7: 7.8202677 | CK7: 7.8202677 | CL7: 7.8202677 | CM7: 7.8202677 | CN7: 7.8202677 | CO7: 7.8202677 | CP7: 7.8202677 | CQ7: 7.8202677 | CR7: 7.8202677 | CS7: 7.8202677 | CT7: 7.8202677 | CU7: 7.8202677 | CV7: 7.8202677 | CW7: 7.8202677 | CX7: 7.8202677
A8: datastructure | B8: WB.DATA360:DS_DATA360(1.3) | C8: I | D8: A | E8: QAT | F8: WB_WDI_ER_H2O_FWST_ZS | G8: _T | H8: _T | I8: _T | J8: PT_FRSH_WAT_RSC | K8: _Z | L8: _Z | M8: _Z | N8: _Z | O8: RATIO | P8: 2 | Q8: WB_WDI | R8: P1Y | S8: Level of water stress: freshwater withdrawal as a proportion of available freshwater resources | T8: 0 | U8: WB_WDI | V8: PU | W8: A | X8: Annual | Y8: Qatar | Z8: Level of water stress: freshwater withdrawal as a proportion of available freshwater resources | AA8: Total | AB8: All age ranges or no breakdown by age | AC8: Total | AD8: Percentage of freshwater resources | AE8: Not Applicable | AF8: Not Applicable | AG8: Not Applicable | AH8: Not Applicable | AI8: Ratio | AJ8: Two | AK8: World Development Indicators (WDI) | AL8: Annual | AM8: Units | AN8: Normal value | AO8: Public | BC8: 258.62069 | BD8: 270.86207 | BE8: 283.10345 | BF8: 295.34483 | BG8: 307.58621 | BH8: 319.82759 | BI8: 332.06897 | BJ8: 344.31034 | BK8: 356.55172 | BL8: 368.7931 | BM8: 381.03448 | BN8: 393.27586 | BO8: 405.51724 | BP8: 417.75862 | BQ8: 430 | BR8: 330.17241 | BS8: 327.75862 | BT8: 325.34483 | BU8: 322.93103 | BV8: 277.06897 | BW8: 277.98851 | BX8: 278.90805 | BY8: 279.82759 | BZ8: 280.74713 | CA8: 281.66667 | CB8: 282.58621 | CC8: 300.89655 | CD8: 321.96552 | CE8: 341.65517 | CF8: 361.34483 | CG8: 374.13793 | CH8: 381.2931 | CI8: 388.44828 | CJ8: 395.60345 | CK8: 402.75862 | CL8: 409.91379 | CM8: 417.06897 | CN8: 424.22414 | CO8: 431.37931 | CP8: 434.65517 | CQ8: 431.03448 | CR8: 432.41379 | CS8: 431.03448 | CT8: 431.03448 | CU8: 431.03448 | CV8: 431.03448 | CW8: 431.03448 | CX8: 431.03448
A9: datastructure | B9: WB.DATA360:DS_DATA360(1.3) | C9: I | D9: A | E9: HUN | F9: WB_WDI_ER_H2O_FWST_ZS | G9: _T | H9: _T | I9: _T | J9: PT_FRSH_WAT_RSC | K9: _Z | L9: _Z | M9: _Z | N9: _Z | O9: RATIO | P9: 2 | Q9: WB_WDI | R9: P1Y | S9: Level of water stress: freshwater withdrawal as a proportion of available freshwater resources | T9: 0 | U9: WB_WDI | V9: PU | W9: A | X9: Annual | Y9: Hungary | Z9: Level of water stress: freshwater withdrawal as a proportion of available freshwater resources | AA9: Total | AB9: All age ranges or no breakdown by age | AC9: Total | AD9: Percentage of freshwater resources | AE9: Not Applicable | AF9: Not Applicable | AG9: Not Applicable | AH9: Not Applicable | AI9: Ratio | AJ9: Two | AK9: World Development Indicators (WDI) | AL9: Annual | AM9: Units | AN9: Normal value | AO9: Public | AX9: 5.1474957 | AY9: 5.4878756 | AZ9: 5.8282556 | BA9: 6.1686356 | BB9: 6.5090155 | BC9: 6.8493955 | BD9: 7.1392746 | BE9: 7.4291537 | BF9: 7.7190328 | BG9: 8.0089119 | BH9: 8.298791 | BI9: 8.8326425 | BJ9: 9.366494 | BK9: 9.9003454 | BL9: 10.434197 | BM9: 10.968048 | BN9: 11.162102 | BO9: 11.356156 | BP9: 11.55021 | BQ9: 11.744264 | BR9: 11.938317 | BS9: 12.132371 | BT9: 12.326425 | BU9: 11.840069 | BV9: 11.353713 | BW9: 10.867358 | BX9: 10.381002 | BY9: 10.308866 | BZ9: 10.23673 | CA9: 10.164594 | CB9: 10.092458 | CC9: 10.020322 | CD9: 9.9481865 | CE9: 9.8537709 | CF9: 9.7593552 | CG9: 9.6649396 | CH9: 9.5705239 | CI9: 9.4761082 | CJ9: 9.3816926 | CK9: 10.953368 | CL9: 9.2746114 | CM9: 9.0241796 | CN9: 8.7236615 | CO9: 9.0673575 | CP9: 6.775475 | CQ9: 6.9602763 | CR9: 6.8376511 | CS9: 8.1805181 | CT9: 8.4947522 | CU9: 7.708247 | CV9: 7.7398964 | CW9: 7.7183074 | CX9: 8.1084974
A10: datastructure | B10: WB.DATA360:DS_DATA360(1.3) | C10: I | D10: A | E10: TKM | F10: WB_WDI_ER_H2O_FWST_ZS | G10: _T | H10: _T | I10: _T | J10: PT_FRSH_WAT_RSC | K10: _Z | L10: _Z | M10: _Z | N10: _Z | O10: RATIO | P10: 2 | Q10: WB_WDI | R10: P1Y | S10: Level of water stress: freshwater withdrawal as a proportion of available freshwater resources | T10: 0 | U10: WB_WDI | V10: PU | W10: A | X10: Annual | Y10: Turkmenistan | Z10: Level of water stress: freshwater withdrawal as a proportion of available freshwater resources | AA10: Total | AB10: All age ranges or no breakdown by age | AC10: Total | AD10: Percentage of freshwater resources | AE10: Not Applicable | AF10: Not Applicable | AG10: Not Applicable | AH10: Not Applicable | AI10: Ratio | AJ10: Two | AK10: World Development Indicators (WDI) | AL10: Annual | AM10: Units | AN10: Normal value | AO10: Public | BV10: 122.09171 | BW10: 123.06122 | BX10: 124.03074 | BY10: 125.00026 | BZ10: 125.96977 | CA10: 126.93929 | CB10: 127.90881 | CC10: 130.93629 | CD10: 133.96376 | CE10: 136.99124 | CF10: 143.56002 | CG10: 143.56002 | CH10: 143.56002 | CI10: 143.69021 | CJ10: 143.8204 | CK10: 143.95059 | CL10: 144.08078 | CM10: 144.21097 | CN10: 144.34116 | CO10: 144.47135 | CP10: 144.60155 | CQ10: 144.73174 | CR10: 144.86193 | CS10: 148.66667 | CT10: 138.48532 | CU10: 142.75167 | CV10: 135.21381 | CW10: 135.21381 | CX10: 135.21381
A11: datastructure | B11: WB.DATA360:DS_DATA360(1.3) | C11: I | D11: A | E11: LBR | F11: WB_WDI_ER_H2O_FWST_ZS | G11: _T | H11: _T | I11: _T | J11: PT_FRSH_WAT_RSC | K11: _Z | L11: _Z | M11: _Z | N11: _Z | O11: RATIO | P11: 2 | Q11: WB_WDI | R11: P1Y | S11: Level of water stress: freshwater withdrawal as a proportion of available freshwater resources | T11: 0 | U11: WB_WDI | V11: PU | W11: A | X11: Annual | Y11: Liberia | Z11: Level of water stress: freshwater withdrawal as a proportion of available freshwater resources | AA11: Total | AB11: All age ranges or no breakdown by age | AC11: Total | AD11: Percentage of freshwater resources | AE11: Not Applicable | AF11: Not Applicable | AG11: Not Applicable | AH11: Not Applicable | AI11: Ratio | AJ11: Two | AK11: World Development Indicators (WDI) | AL11: Annual | AM11: Units | AN11: Normal value | AO11: Public | BO11: 0.23550725 | BP11: 0.23561873 | BQ11: 0.23573021 | BR11: 0.23584169 | BS11: 0.23595318 | BT11: 0.23606466 | BU11: 0.23617614 | BV11: 0.23628763 | BW11: 0.23639911 | BX11: 0.23651059 | BY11: 0.23662207 | BZ11: 0.23673356 | CA11: 0.23684504 | CB11: 0.23695652 | CC11: 0.24242754 | CD11: 0.24789855 | CE11: 0.25336957 | CF11: 0.25884058 | CG11: 0.26431159 | CH11: 0.26431159 | CI11: 0.26431159 | CJ11: 0.26431159 | CK11: 0.26431159 | CL11: 0.26431159 | CM11: 0.26431159 | CN11: 0.26431159 | CO11: 0.26431159 | CP11: 0.26431159 | CQ11: 0.26431159 | CR11: 0.26431159 | CS11: 0.26431159 | CT11: 0.26431159 | CU11: 0.26431159 | CV11: 0.26431159 | CW11: 0.26431159 | CX11: 0.26431159
A12: datastructure | B12: WB.DATA360:DS_DATA360(1.3) | C12: I | D12: A | E12: TJK | F12: WB_WDI_ER_H2O_FWST_ZS | G12: _T | H12: _T | I12: _T | J12: PT_FRSH_WAT_RSC | K12: _Z | L12: _Z | M12: _Z | N12: _Z | O12: RATIO | P12: 2 | Q12: WB_WDI | R12: P1Y | S12: Level of water stress: freshwater withdrawal as a proportion of available freshwater resources | T12: 0 | U12: WB_WDI | V12: PU | W12: A | X12: Annual | Y12: Tajikistan | Z12: Level of water stress: freshwater withdrawal as a proportion of available freshwater resources | AA12: Total | AB12: All age ranges or no breakdown by age | AC12: Total | AD12: Percentage of freshwater resources | AE12: Not Applicable | AF12: Not Applicable | AG12: Not Applicable | AH12: Not Applicable | AI12: Ratio | AJ12: Two | AK12: World Development Indicators (WDI) | AL12: Annual | AM12: Units | AN12: Normal value | AO12: Public | BV12: 75.999472 | BW12: 76.867001 | BX12: 77.73453 | BY12: 78.602058 | BZ12: 79.469587 | CA12: 80.337116 | CB12: 81.204644 | CC12: 79.979549 | CD12: 78.754453 | CE12: 77.529357 | CF12: 76.304262 | CG12: 75.079166 | CH12: 73.85407 | CI12: 73.28598 | CJ12: 72.71789 | CK12: 72.1498 | CL12: 71.58171 | CM12: 71.01362 | CN12: 70.445529 | CO12: 69.877439 | CP12: 69.309349 | CQ12: 68.741259 | CR12: 57.718696 | CS12: 52.698245 | CT12: 64.480802 | CU12: 69.943264 | CV12: 69.943264 | CW12: 69.943264 | CX12: 69.943264
A13: datastructure | B13: WB.DATA360:DS_DATA360(1.3) | C13: I | D13: A | E13: CPV | F13: WB_WDI_ER_H2O_FWST_ZS | G13: _T | H13: _T | I13: _T | J13: PT_FRSH_WAT_RSC | K13: _Z | L13: _Z | M13: _Z | N13: _Z | O13: RATIO | P13: 2 | Q13: WB_WDI | R13: P1Y | S13: Level of water stress: freshwater withdrawal as a proportion of available freshwater resources | T13: 0 | U13: WB_WDI | V13: PU | W13: A | X13: Annual | Y13: Cabo Verde | Z13: Level of water stress: freshwater withdrawal as a proportion of available freshwater resources | AA13: Total | AB13: All age ranges or no breakdown by age | AC13: Total | AD13: Percentage of freshwater resources | AE13: Not Applicable | AF13: Not Applicable | AG13: Not Applicable | AH13: Not Applicable | AI13: Ratio | AJ13: Two | AK13: World Development Indicators (WDI) | AL13: Annual | AM13: Units | AN13: Normal value | AO13: Public | CC13: 7.1833333 | CD13: 8.5342087 | CE13: 9.8850841 | CF13: 11.235959 | CG13: 13.604034 | CH13: 15.972109 | CI13: 18.340184 | CJ13: 20.708259 | CK13: 23.076334 | CL13: 25.444409 | CM13: 27.812484 | CN13: 30.180559 | CO13: 32.548634 | CP13: 34.916709 | CQ13: 37.284784 | CR13: 39.652859 | CS13: 42.020933 | CT13: 44.389008 | CU13: 48.95751 | CV13: 68.943737 | CW13: 57.177507 | CX13: 59.68371
A14: datastructure | B14: WB.DATA360:DS_DATA360(1.3) | C14: I | D14: A | E14: DZA | F14: WB_WDI_ER_H2O_FWST_ZS | G14: _T | H14: _T | I14: _T | J14: PT_FRSH_WAT_RSC | K14: _Z | L14: _Z | M14: _Z | N14: _Z | O14: RATIO | P14: 2 | Q14: WB_WDI | R14: P1Y | S14: Level of water stress: freshwater withdrawal as a proportion of available freshwater resources | T14: 0 | U14: WB_WDI | V14: PU | W14: A | X14: Annual | Y14: Algeria | Z14: Level of water stress: freshwater withdrawal as a proportion of available freshwater resources | AA14: Total | AB14: All age ranges or no breakdown by age | AC14: Total | AD14: Percentage of freshwater resources | AE14: Not Applicable | AF14: Not Applicable | AG14: Not Applicable | AH14: Not Applicable | AI14: Ratio | AJ14: Two | AK14: World Development Indicators (WDI) | AL14: Annual | AM14: Units | AN14: Normal value | AO14: Public | AX14: 28.141269 | AY14: 29.548333 | AZ14: 30.955396 | BA14: 32.36246 | BB14: 33.769523 | BC14: 35.176586 | BD14: 36.58365 | BE14: 37.990713 | BF14: 39.397777 | BG14: 40.80484 | BH14: 42.211904 | BI14: 43.618967 | BJ14: 45.026031 | BK14: 46.433094 | BL14: 47.840158 | BM14: 49.247221 | BN14: 52.061348 | BO14: 54.875475 | BP14: 57.689602 | BQ14: 60.503729 | BR14: 62.417335 | BS14: 64.101718 | BT14: 65.786101 | BU14: 67.470484 | BV14: 69.154867 | BW14: 70.839249 | BX14: 72.523632 | BY14: 74.208015 | BZ14: 75.892398 | CA14: 77.576781 | CB14: 79.261164 | CC14: 81.71052 | CD14: 85.037372 | CE14: 87.522801 | CF14: 90.008229 | CG14: 92.493658 | CH14: 94.979086 | CI14: 97.464514 | CJ14: 99.949943 | CK14: 102.43537 | CL14: 104.9208 | CM14: 107.40623 | CN14: 109.75095 | CO14: 115.16345 | CP14: 120.57596 | CQ14: 125.98846 | CR14: 129.87196 | CS14: 137.92036 | CT14: 141.79917 | CU14: 145.67797 | CV14: 149.55677 | CW14: 140.59378 | CX14: 144.81497
A15: datastructure | B15: WB.DATA360:DS_DATA360(1.3) | C15: I | D15: A | E15: ARE | F15: WB_WDI_ER_H2O_FWST_ZS | G15: _T | H15: _T | I15: _T | J15: PT_FRSH_WAT_RSC | K15: _Z | L15: _Z | M15: _Z | N15: _Z | O15: RATIO | P15: 2 | Q15: WB_WDI | R15: P1Y | S15: Level of water stress: freshwater withdrawal as a proportion of available freshwater resources | T15: 0 | U15: WB_WDI | V15: PU | W15: A | X15: Annual | Y15: United Arab Emirates | Z15: Level of water stress: freshwater withdrawal as a proportion of available freshwater resources | AA15: Total | AB15: All age ranges or no breakdown by age | AC15: Total | AD15: Percentage of freshwater resources | AE15: Not Applicable | AF15: Not Applicable | AG15: Not Applicable | AH15: Not Applicable | AI15: Ratio | AJ15: Two | AK15: World Development Indicators (WDI) | AL15: Annual | AM15: Units | AN15: Normal value | AO15: Public | BH15: 600 | BI15: 653.68889 | BJ15: 707.37778 | BK15: 761.06667 | BL15: 814.75556 | BM15: 868.44444 | BN15: 922.13333 | BO15: 975.82222 | BP15: 1029.5111 | BQ15: 1083.2 | BR15: 1028.2222 | BS15: 1052.3111 | BT15: 1076.4 | BU15: 1100.4889 | BV15: 1124.5778 | BW15: 1148.6667 | BX15: 1254.8133 | BY15: 1360.96 | BZ15: 1467.1067 | CA15: 1573.2533 | CB15: 1555.8667 | CC15: 1527.9289 | CD15: 1499.9911 | CE15: 1472.0533 | CF15: 1669.36 | CG15: 1866.6667 | CH15: 1849.6364 | CI15: 1832.6061 | CJ15: 1815.5758 | CK15: 1798.5455 | CL15: 1781.5152 | CM15: 1764.4848 | CN15: 1747.4545 | CO15: 1730.4242 | CP15: 1713.3939 | CQ15: 1696.3636 | CR15: 1679.3333 | CS15: 1630 | CT15: 1667.3333 | CU15: 1628.6667 | CV15: 1587.3333 | CW15: 1533.3333 | CX15: 1509.9333
A16: datastructure | B16: WB.DATA360:DS_DATA360(1.3) | C16: I | D16: A | E16: ETH | F16: WB_WDI_ER_H2O_FWST_ZS | G16: _T | H16: _T | I16: _T | J16: PT_FRSH_WAT_RSC | K16: _Z | L16: _Z | M16: _Z | N16: _Z | O16: RATIO | P16: 2 | Q16: WB_WDI | R16: P1Y | S16: Level of water stress: freshwater withdrawal as a proportion of available freshwater resources | T16: 0 | U16: WB_WDI | V16: PU | W16: A | X16: Annual | Y16: Ethiopia | Z16: Level of water stress: freshwater withdrawal as a proportion of available freshwater resources | AA16: Total | AB16: All age ranges or no breakdown by age | AC16: Total | AD16: Percentage of freshwater resources | AE16: Not Applicable | AF16: Not Applicable | AG16: Not Applicable | AH16: Not Applicable | AI16: Ratio | AJ16: Two | AK16: World Development Indicators (WDI) | AL16: Annual | AM16: Units | AN16: Normal value | AO16: Public | CD16: 16.996942 | CE16: 19.344648 | CF16: 21.692355 | CG16: 24.040061 | CH16: 24.787073 | CI16: 25.53514 | CJ16: 26.28268 | CK16: 27.028107 | CL16: 27.775118 | CM16: 28.52213 | CN16: 29.269141 | CO16: 30.016152 | CP16: 30.763164 | CQ16: 31.510175 | CR16: 32.262997 | CS16: 32.257187 | CT16: 32.257187 | CU16: 32.257187 | CV16: 32.257187 | CW16: 32.257187 | CX16: 32.257187
A17: datastructure | B17: WB.DATA360:DS_DATA360(1.3) | C17: I | D17: A | E17: PRT | F17: WB_WDI_ER_H2O_FWST_ZS | G17: _T | H17: _T | I17: _T | J17: PT_FRSH_WAT_RSC | K17: _Z | L17: _Z | M17: _Z | N17: _Z | O17: RATIO | P17: 2 | Q17: WB_WDI | R17: P1Y | S17: Level of water stress: freshwater withdrawal as a proportion of available freshwater resources | T17: 0 | U17: WB_WDI | V17: PU | W17: A | X17: Annual | Y17: Portugal | Z17: Level of water stress: freshwater withdrawal as a proportion of available freshwater resources | AA17: Total | AB17: All age ranges or no breakdown by age | AC17: Total | AD17: Percentage of freshwater resources | AE17: Not Applicable | AF17: Not Applicable | AG17: Not Applicable | AH17: Not Applicable | AI17: Ratio | AJ17: Two | AK17: World Development Indicators (WDI) | AL17: Annual | AM17: Units | AN17: Normal value | AO17: Public | BS17: 17.276271 | BT17: 20.233397 | BU17: 23.190524 | BV17: 26.147651 | BW17: 25.823014 | BX17: 24.67258 | BY17: 23.522145 | BZ17: 22.37171 | CA17: 21.90282 | CB17: 21.427902 | CC17: 20.959013 | CD17: 20.490123 | CE17: 20.021233 | CF17: 19.552343 | CG17: 19.083453 | CH17: 18.20132 | CI17: 18.376532 | CJ17: 18.242493 | CK17: 18.108454 | CL17: 17.974416 | CM17: 17.840377 | CN17: 17.706338 | CO17: 17.572299 | CP17: 17.43826 | CQ17: 17.304222 | CR17: 17.170183 | CS17: 12.379887 | CT17: 12.315712 | CU17: 12.315712 | CV17: 12.315712 | CW17: 12.315712 | CX17: 12.315712
A18: datastructure | B18: WB.DATA360:DS_DATA360(1.3) | C18: I | D18: A | E18: BOL | F18: WB_WDI_ER_H2O_FWST_ZS | G18: _T | H18: _T | I18: _T | J18: PT_FRSH_WAT_RSC | K18: _Z | L18: _Z | M18: _Z | N18: _Z | O18: RATIO | P18: 2 | Q18: WB_WDI | R18: P1Y | S18: Level of water stress: freshwater withdrawal as a proportion of available freshwater resources | T18: 0 | U18: WB_WDI | V18: PU | W18: A | X18: Annual | Y18: Bolivia | Z18: Level of water stress: freshwater withdrawal as a proportion of available freshwater resources | AA18: Total | AB18: All age ranges or no breakdown by age | AC18: Total | AD18: Percentage of freshwater resources | AE18: Not Applicable | AF18: Not Applicable | AG18: Not Applicable | AH18: Not Applicable | AI18: Ratio | AJ18: Two | AK18: World Development Indicators (WDI) | AL18: Annual | AM18: Units | AN18: Normal value | AO18: Public | BO18: 0.69898534 | BP18: 0.73248693 | BQ18: 0.76598852 | BR18: 0.79949011 | BS18: 0.8329917 | BT18: 0.86649329 | BU18: 0.89999488 | BV18: 0.93349646 | BW18: 0.96699805 | BX18: 1.0004996 | BY18: 1.0340012 | BZ18: 1.0675028 | CA18: 1.1010044 | CB18: 1.1094997 | CC18: 1.1179951 | CD18: 1.1264904 | CE18: 1.1349857 | CF18: 1.143481 | CG18: 1.1519764 | CH18: 1.1604717 | CI18: 1.168967 | CJ18: 1.1770011 | CK18: 1.1770011 | CL18: 1.1835549 | CM18: 1.1901087 | CN18: 1.1966625 | CO18: 1.2032163 | CP18: 1.2097701 | CQ18: 1.2163239 | CR18: 1.2228777 | CS18: 1.2294315 | CT18: 1.2359853 | CU18: 1.2425391 | CV18: 0.20736554 | CW18: 0.20297959 | CX18: 0.20297959
A19: datastructure | B19: WB.DATA360:DS_DATA360(1.3) | C19: I | D19: A | E19: CAF | F19: WB_WDI_ER_H2O_FWST_ZS | G19: _T | H19: _T | I19: _T | J19: PT_FRSH_WAT_RSC | K19: _Z | L19: _Z | M19: _Z | N19: _Z | O19: RATIO | P19: 2 | Q19: WB_WDI | R19: P1Y | S19: Level of water stress: freshwater withdrawal as a proportion of available freshwater resources | T19: 0 | U19: WB_WDI | V19: PU | W19: A | X19: Annual | Y19: Central African Republic | Z19: Level of water stress: freshwater withdrawal as a proportion of available freshwater resources | AA19: Total | AB19: All age ranges or no breakdown by age | AC19: Total | AD19: Percentage of freshwater resources | AE19: Not Applicable | AF19: Not Applicable | AG19: Not Applicable | AH19: Not Applicable | AI19: Ratio | AJ19: Two | AK19: World Development Indicators (WDI) | AL19: Annual | AM19: Units | AN19: Normal value | AO19: Public | BO19: 0.089814815 | BP19: 0.10648148 | BQ19: 0.12314815 | BR19: 0.13981482 | BS19: 0.15648148 | BT19: 0.17314815 | BU19: 0.18981481 | BV19: 0.20648148 | BW19: 0.22314815 | BX19: 0.23981481 | BY19: 0.25648148 | BZ19: 0.27314815 | CA19: 0.28981482 | CB19: 0.30648148 | CC19: 0.31231482 | CD19: 0.31814815 | CE19: 0.32398148 | CF19: 0.32981481 | CG19: 0.33564815 | CH19: 0.33564815 | CI19: 0.33564815 | CJ19: 0.33564815 | CK19: 0.33564815 | CL19: 0.33564815 | CM19: 0.33564815 | CN19: 0.33564815 | CO19: 0.33564815 | CP19: 0.33564815 | CQ19: 0.33564815 | CR19: 0.33564815 | CS19: 0.33564815 | CT19: 0.33564815 | CU19: 0.33564815 | CV19: 0.33564815 | CW19: 0.33564815 | CX19: 0.33564815
A20: datastructure | B20: WB.DATA360:DS_DATA360(1.3) | C20: I | D20: A | E20: LKA | F20: WB_WDI_ER_H2O_FWST_ZS | G20: _T | H20: _T | I20: _T | J20: PT_FRSH_WAT_RSC | K20: _Z | L20: _Z | M20: _Z | N20: _Z | O20: RATIO | P20: 2 | Q20: WB_WDI | R20: P1Y | S20: Level of water stress: freshwater withdrawal as a proportion of available freshwater resources | T20: 0 | U20: WB_WDI | V20: PU | W20: A | X20: Annual | Y20: Sri Lanka | Z20: Level of water stress: freshwater withdrawal as a proportion of available freshwater resources | AA20: Total | AB20: All age ranges or no breakdown by age | AC20: Total | AD20: Percentage of freshwater resources | AE20: Not Applicable | AF20: Not Applicable | AG20: Not Applicable | AH20: Not Applicable | AI20: Ratio | AJ20: Two | AK20: World Development Indicators (WDI) | AL20: Annual | AM20: Units | AN20: Normal value | AO20: Public | BR20: 68.506311 | BS20: 70.779523 | BT20: 73.052735 | BU20: 75.325947 | BV20: 77.599158 | BW20: 79.87237 | BX20: 82.145582 | BY20: 84.418794 | BZ20: 86.692006 | CA20: 88.965217 | CB20: 91.238429 | CC20: 91.147826 | CD20: 91.057223 | CE20: 90.96662 | CF20: 90.876017 | CG20: 90.785414 | CH20: 90.785414 | CI20: 90.785414 | CJ20: 90.785414 | CK20: 90.785414 | CL20: 90.785414 | CM20: 90.785414 | CN20: 90.785414 | CO20: 90.785414 | CP20: 90.785414 | CQ20: 90.785414 | CR20: 90.785414 | CS20: 90.785414 | CT20: 90.785414 | CU20: 90.785414 | CV20: 90.785414 | CW20: 90.785414 | CX20: 90.785414
A21: datastructure | B21: WB.DATA360:DS_DATA360(1.3) | C21: I | D21: A | E21: AUT | F21: WB_WDI_ER_H2O_FWST_ZS | G21: _T | H21: _T | I21: _T | J21: PT_FRSH_WAT_RSC | K21: _Z | L21: _Z | M21: _Z | N21: _Z | O21: RATIO | P21: 2 | Q21: WB_WDI | R21: P1Y | S21: Level of water stress: freshwater withdrawal as a proportion of available freshwater resources | T21: 0 | U21: WB_WDI | V21: PU | W21: A | X21: Annual | Y21: Austria | Z21: Level of water stress: freshwater withdrawal as a proportion of available freshwater resources | AA21: Total | AB21: All age ranges or no breakdown by age | AC21: Total | AD21: Percentage of freshwater resources | AE21: Not Applicable | AF21: Not Applicable | AG21: Not Applicable | AH21: Not Applicable | AI21: Ratio | AJ21: Two | AK21: World Development Indicators (WDI) | AL21: Annual | AM21: Units | AN21: Normal value | AO21: Public | BH21: 9.2290688 | BI21: 9.3600442 | BJ21: 9.4910196 | BK21: 9.621995 | BL21: 9.7529704 | BM21: 9.8839458 | BN21: 10.009948 | BO21: 10.135949 | BP21: 10.261951 | BQ21: 10.387952 | BR21: 10.513954 | BS21: 10.316109 | BT21: 10.118265 | BU21: 9.92042 | BV21: 9.7225753 | BW21: 9.5247306 | BX21: 9.794142 | BY21: 10.063553 | BZ21: 10.096712 | CA21: 10.12987 | CB21: 10.046974 | CC21: 9.9668417 | CD21: 9.8839458 | CE21: 9.8538961 | CF21: 9.8238464 | CG21: 9.7937966 | CH21: 9.7637469 | CI21: 9.7336972 | CJ21: 9.7036474 | CK21: 9.6735977 | CL21: 9.6435479 | CM21: 9.5360904 | CN21: 9.4286328 | CO21: 9.3211753 | CP21: 9.2137177 | CQ21: 9.1062602 | CR21: 8.9988026 | CS21: 8.8913451 | CT21: 8.7838875 | CU21: 8.67643 | CV21: 8.67643 | CW21: 8.67643 | CX21: 8.67643
A22: datastructure | B22: WB.DATA360:DS_DATA360(1.3) | C22: I | D22: A | E22: JAM | F22: WB_WDI_ER_H2O_FWST_ZS | G22: _T | H22: _T | I22: _T | J22: PT_FRSH_WAT_RSC | K22: _Z | L22: _Z | M22: _Z | N22: _Z | O22: RATIO | P22: 2 | Q22: WB_WDI | R22: P1Y | S22: Level of water stress: freshwater withdrawal as a proportion of available freshwater resources | T22: 0 | U22: WB_WDI | V22: PU | W22: A | X22: Annual | Y22: Jamaica | Z22: Level of water stress: freshwater withdrawal as a proportion of available freshwater resources | AA22: Total | AB22: All age ranges or no breakdown by age | AC22: Total | AD22: Percentage of freshwater resources | AE22: Not Applicable | AF22: Not Applicable | AG22: Not Applicable | AH22: Not Applicable | AI22: Ratio | AJ22: Two | AK22: World Development Indicators (WDI) | AL22: Annual | AM22: Units | AN22: Normal value | AO22: Public | BU22: 8.5697126 | BV22: 8.8436003 | BW22: 9.1174879 | BX22: 9.3913755 | BY22: 9.6652631 | BZ22: 9.9391507 | CA22: 10.213038 | CB22: 10.486926 | CC22: 10.760814 | CD22: 11.034701 | CE22: 11.308589 | CF22: 11.582476 | CG22: 11.856364 | CH22: 12.130252 | CI22: 12.404139 | CJ22: 12.678027 | CK22: 12.951915 | CL22: 13.225802 | CM22: 13.49969 | CN22: 13.773577 | CO22: 14.047465 | CP22: 14.321353 | CQ22: 7.6688534 | CR22: 12.473436 | CS22: 12.34396 | CT22: 12.214484 | CU22: 12.085008 | CV22: 11.046431 | CW22: 12.382819 | CX22: 12.382819
A23: datastructure | B23: WB.DATA360:DS_DATA360(1.3) | C23: I | D23: A | E23: HND | F23: WB_WDI_ER_H2O_FWST_ZS | G23: _T | H23: _T | I23: _T | J23: PT_FRSH_WAT_RSC | K23: _Z | L23: _Z | M23: _Z | N23: _Z | O23: RATIO | P23: 2 | Q23: WB_WDI | R23: P1Y | S23: Level of water stress: freshwater withdrawal as a proportion of available freshwater resources | T23: 0 | U23: WB_WDI | V23: PU | W23: A | X23: Annual | Y23: Honduras | Z23: Level of water stress: freshwater withdrawal as a proportion of available freshwater resources | AA23: Total | AB23: All age ranges or no breakdown by age | AC23: Total | AD23: Percentage of freshwater resources | AE23: Not Applicable | AF23: Not Applicable | AG23: Not Applicable | AH23: Not Applicable | AI23: Ratio | AJ23: Two | AK23: World Development Indicators (WDI) | AL23: Annual | AM23: Units | AN23: Normal value | AO23: Public | CE23: 4.6212688 | CF23: 4.6212688 | CG23: 4.6212688 | CH23: 4.6212688 | CI23: 4.6212688 | CJ23: 4.6212688 | CK23: 4.6212688 | CL23: 4.6212688 | CM23: 4.6212688 | CN23: 4.6212688 | CO23: 4.6212688 | CP23: 4.6212688 | CQ23: 4.6212688 | CR23: 4.6212688 | CS23: 4.6212688 | CT23: 4.6212688 | CU23: 4.6212688 | CV23: 4.6212688 | CW23: 4.6212688 | CX23: 4.6212688
A24: datastructure | B24: WB.DATA360:DS_DATA360(1.3) | C24: I | D24: A | E24: BDI | F24: WB_WDI_ER_H2O_FWST_ZS | G24: _T | H24: _T | I24: _T | J24: PT_FRSH_WAT_RSC | K24: _Z | L24: _Z | M24: _Z | N24: _Z | O24: RATIO | P24: 2 | Q24: WB_WDI | R24: P1Y | S24: Level of water stress: freshwater withdrawal as a proportion of available freshwater resources | T24: 0 | U24: WB_WDI | V24: PU | W24: A | X24: Annual | Y24: Burundi | Z24: Level of water stress: freshwater withdrawal as a proportion of available freshwater resources | AA24: Total | AB24: All age ranges or no breakdown by age | AC24: Total | AD24: Percentage of freshwater resources | AE24: Not Applicable | AF24: Not Applicable | AG24: Not Applicable | AH24: Not Applicable | AI24: Ratio | AJ24: Two | AK24: World Development Indicators (WDI) | AL24: Annual | AM24: Units | AN24: Normal value | AO24: Public | BO24: 3.6390102 | BP24: 4.165267 | BQ24: 4.6915239 | BR24: 5.2177808 | BS24: 5.7440376 | BT24: 6.2702945 | BU24: 6.7965513 | BV24: 7.3228082 | BW24: 7.8490651 | BX24: 8.3753219 | BY24: 8.9015788 | BZ24: 9.4278356 | CA24: 9.9540925 | CB24: 10.480349 | CC24: 10.422853 | CD24: 10.365357 | CE24: 10.30786 | CF24: 10.250364 | CG24: 10.192868 | CH24: 10.192868 | CI24: 10.192868 | CJ24: 10.192868 | CK24: 10.192868 | CL24: 10.192868 | CM24: 10.192868 | CN24: 10.192868 | CO24: 10.192868 | CP24: 10.192868 | CQ24: 10.192868 | CR24: 10.192868 | CS24: 10.192868 | CT24: 10.192868 | CU24: 10.192868 | CV24: 10.192868 | CW24: 10.192868 | CX24: 10.192868
A25: datastructure | B25: WB.DATA360:DS_DATA360(1.3) | C25: I | D25: A | E25: PAN | F25: WB_WDI_ER_H2O_FWST_ZS | G25: _T | H25: _T | I25: _T | J25: PT_FRSH_WAT_RSC | K25: _Z | L25: _Z | M25: _Z | N25: _Z | O25: RATIO | P25: 2 | Q25: WB_WDI | R25: P1Y | S25: Level of water stress: freshwater withdrawal as a proportion of available freshwater resources | T25: 0 | U25: WB_WDI | V25: PU | W25: A | X25: Annual | Y25: Panama | Z25: Level of water stress: freshwater withdrawal as a proportion of available freshwater resources | AA25: Total | AB25: All age ranges or no breakdown by age | AC25: Total | AD25: Percentage of freshwater resources | AE25: Not Applicable | AF25: Not Applicable | AG25: Not Applicable | AH25: Not Applicable | AI25: Ratio | AJ25: Two | AK25: World Development Indicators (WDI) | AL25: Annual | AM25: Units | AN25: Normal value | AO25: Public | CL25: 0.77134781 | CM25: 0.81543192 | CN25: 0.85951602 | CO25: 0.90360012 | CP25: 0.8934097 | CQ25: 0.93074978 | CR25: 0.90107111 | CS25: 0.90107111 | CT25: 0.90107111 | CU25: 0.90107111 | CV25: 0.90107111 | CW25: 0.90107111 | CX25: 0.90107111
A26: datastructure | B26: WB.DATA360:DS_DATA360(1.3) | C26: I | D26: A | E26: OMN | F26: WB_WDI_ER_H2O_FWST_ZS | G26: _T | H26: _T | I26: _T | J26: PT_FRSH_WAT_RSC | K26: _Z | L26: _Z | M26: _Z | N26: _Z | O26: RATIO | P26: 2 | Q26: WB_WDI | R26: P1Y | S26: Level of water stress: freshwater withdrawal as a proportion of available freshwater resources | T26: 0 | U26: WB_WDI | V26: PU | W26: A | X26: Annual | Y26: Oman | Z26: Level of water stress: freshwater withdrawal as a proportion of available freshwater resources | AA26: Total | AB26: All age ranges or no breakdown by age | AC26: Total | AD26: Percentage of freshwater resources | AE26: Not Applicable | AF26: Not Applicable | AG26: Not Applicable | AH26: Not Applicable | AI26: Ratio | AJ26: Two | AK26: World Development Indicators (WDI) | AL26: Annual | AM26: Units | AN26: Normal value | AO26: Public | BS26: 85.5 | BT26: 86.473665 | BU26: 87.44733 | BV26: 88.420996 | BW26: 86.966089 | BX26: 87.939755 | BY26: 88.91342 | BZ26: 89.887085 | CA26: 90.86075 | CB26: 92.857143 | CC26: 90.792208 | CD26: 89.75 | CE26: 84.714286 | CF26: 87.914286 | CG26: 91.114286 | CH26: 94.314286 | CI26: 97.514286 | CJ26: 100.71429 | CK26: 103.91429 | CL26: 107.11429 | CM26: 110.31429 | CN26: 113.51429 | CO26: 116.71429 | CP26: 116.71429 | CQ26: 116.71429 | CR26: 116.71429 | CS26: 116.71429 | CT26: 116.71429 | CU26: 116.71429 | CV26: 116.71429 | CW26: 116.71429 | CX26: 116.71429
A27: datastructure | B27: WB.DATA360:DS_DATA360(1.3) | C27: I | D27: A | E27: CHN | F27: WB_WDI_ER_H2O_FWST_ZS | G27: _T | H27: _T | I27: _T | J27: PT_FRSH_WAT_RSC | K27: _Z | L27: _Z | M27: _Z | N27: _Z | O27: RATIO | P27: 2 | Q27: WB_WDI | R27: P1Y | S27: Level of water stress: freshwater withdrawal as a proportion of available freshwater resources | T27: 0 | U27: WB_WDI | V27: PU | W27: A | X27: Annual | Y27: China | Z27: Level of water stress: freshwater withdrawal as a proportion of available freshwater resources | AA27: Total | AB27: All age ranges or no breakdown by age | AC27: Total | AD27: Percentage of freshwater resources | AE27: Not Applicable | AF27: Not Applicable | AG27: Not Applicable | AH27: Not Applicable | AI27: Ratio | AJ27: Two | AK27: World Development Indicators (WDI) | AL27: Annual | AM27: Units | AN27: Normal value | AO27: Public | BH27: 32.405311 | BI27: 33.017521 | BJ27: 33.629731 | BK27: 34.241941 | BL27: 34.854151 | BM27: 35.133872 | BN27: 35.410526 | BO27: 35.68718 | BP27: 35.963833 | BQ27: 36.240487 | BR27: 36.517141 | BS27: 37.135498 | BT27: 37.753855 | BU27: 38.372212 | BV27: 38.638265 | BW27: 38.904319 | BX27: 39.170372 | BY27: 39.436426 | BZ27: 39.702479 | CA27: 39.968533 | CB27: 40.234586 | CC27: 40.281328 | CD27: 40.32807 | CE27: 40.374812 | CF27: 40.421554 | CG27: 40.468296 | CH27: 41.483472 | CI27: 41.534596 | CJ27: 42.07505 | CK27: 42.593593 | CL27: 42.858708 | CM27: 43.455398 | CN27: 43.732928 | CO27: 44.025065 | CP27: 43.338543 | CQ27: 43.221688 | CR27: 44.114167 | CS27: 43.5445 | CT27: 43.302756 | CU27: 43.212194 | CV27: 41.518529 | CW27: 41.518529 | CX27: 41.518529
A28: datastructure | B28: WB.DATA360:DS_DATA360(1.3) | C28: I | D28: A | E28: CUB | F28: WB_WDI_ER_H2O_FWST_ZS | G28: _T | H28: _T | I28: _T | J28: PT_FRSH_WAT_RSC | K28: _Z | L28: _Z | M28: _Z | N28: _Z | O28: RATIO | P28: 2 | Q28: WB_WDI | R28: P1Y | S28: Level of water stress: freshwater withdrawal as a proportion of available freshwater resources | T28: 0 | U28: WB_WDI | V28: PU | W28: A | X28: Annual | Y28: Cuba | Z28: Level of water stress: freshwater withdrawal as a proportion of available freshwater resources | AA28: Total | AB28: All age ranges or no breakdown by age | AC28: Total | AD28: Percentage of freshwater resources | AE28: Not Applicable | AF28: Not Applicable | AG28: Not Applicable | AH28: Not Applicable | AI28: Ratio | AJ28: Two | AK28: World Development Indicators (WDI) | AL28: Annual | AM28: Units | AN28: Normal value | AO28: Public | BW28: 17.92878 | BX28: 17.94621 | BY28: 17.963639 | BZ28: 17.981069 | CA28: 17.998499 | CB28: 18.015928 | CC28: 18.031982 | CD28: 18.049411 | CE28: 18.066841 | CF28: 18.08427 | CG28: 18.1017 | CH28: 18.11913 | CI28: 16.983657 | CJ28: 19.741442 | CK28: 20.837433 | CL28: 20.708584 | CM28: 21.786226 | CN28: 22.863868 | CO28: 23.939446 | CP28: 23.939446 | CQ28: 23.939446 | CR28: 23.939446 | CS28: 23.939446 | CT28: 23.939446 | CU28: 23.939446 | CV28: 23.939446 | CW28: 23.939446 | CX28: 23.939446
A29: datastructure | B29: WB.DATA360:DS_DATA360(1.3) | C29: I | D29: A | E29: GAB | F29: WB_WDI_ER_H2O_FWST_ZS | G29: _T | H29: _T | I29: _T | J29: PT_FRSH_WAT_RSC | K29: _Z | L29: _Z | M29: _Z | N29: _Z | O29: RATIO | P29: 2 | Q29: WB_WDI | R29: P1Y | S29: Level of water stress: freshwater withdrawal as a proportion of available freshwater resources | T29: 0 | U29: WB_WDI | V29: PU | W29: A | X29: Annual | Y29: Gabon | Z29: Level of water stress: freshwater withdrawal as a proportion of available freshwater resources | AA29: Total | AB29: All age ranges or no breakdown by age | AC29: Total | AD29: Percentage of freshwater resources | AE29: Not Applicable | AF29: Not Applicable | AG29: Not Applicable | AH29: Not Applicable | AI29: Ratio | AJ29: Two | AK29: World Development Indicators (WDI) | AL29: Annual | AM29: Units | AN29: Normal value | AO29: Public | BO29: 0.2166065 | BP29: 0.23335185 | BQ29: 0.25009719 | BR29: 0.26684254 | BS29: 0.28358789 | BT29: 0.30033324 | BU29: 0.31707859 | BV29: 0.33382394 | BW29: 0.35056929 | BX29: 0.36731464 | BY29: 0.38405998 | BZ29: 0.40080533 | CA29: 0.41755068 | CB29: 0.43429603 | CC29: 0.44787004 | CD29: 0.46144404 | CE29: 0.47501805 | CF29: 0.48859206 | CG29: 0.50216607 | CH29: 0.50216607 | CI29: 0.50216607 | CJ29: 0.50216607 | CK29: 0.50216607 | CL29: 0.50216607 | CM29: 0.50216607 | CN29: 0.50216607 | CO29: 0.50216607 | CP29: 0.50216607 | CQ29: 0.50216607 | CR29: 0.50216607 | CS29: 0.50216607 | CT29: 0.50216607 | CU29: 0.50216607 | CV29: 0.50216607 | CW29: 0.50216607 | CX29: 0.50216607
A30: datastructure | B30: WB.DATA360:DS_DATA360(1.3) | C30: I | D30: A | E30: IRN | F30: WB_WDI_ER_H2O_FWST_ZS | G30: _T | H30: _T | I30: _T | J30: PT_FRSH_WAT_RSC | K30: _Z | L30: _Z | M30: _Z | N30: _Z | O30: RATIO | P30: 2 | Q30: WB_WDI | R30: P1Y | S30: Level of water stress: freshwater withdrawal as a proportion of available freshwater resources | T30: 0 | U30: WB_WDI | V30: PU | W30: A | X30: Annual | Y30: Iran, Islamic Rep. | Z30: Level of water stress: freshwater withdrawal as a proportion of available freshwater resources | AA30: Total | AB30: All age ranges or no breakdown by age | AC30: Total | AD30: Percentage of freshwater resources | AE30: Not Applicable | AF30: Not Applicable | AG30: Not Applicable | AH30: Not Applicable | AI30: Ratio | AJ30: Two | AK30: World Development Indicators (WDI) | AL30: Annual | AM30: Units | AN30: Normal value | AO30: Public | BC30: 39.354585 | BD30: 40.570982 | BE30: 41.787378 | BF30: 43.003775 | BG30: 44.220172 | BH30: 45.436569 | BI30: 46.65384 | BJ30: 47.870383 | BK30: 49.086925 | BL30: 50.303468 | BM30: 51.52001 | BN30: 52.736553 | BO30: 53.953095 | BP30: 55.169638 | BQ30: 56.38618 | BR30: 57.602723 | BS30: 58.816933 | BT30: 60.03333 | BU30: 61.249727 | BV30: 66.917224 | BW30: 72.584722 | BX30: 73.546723 | BY30: 74.508724 | BZ30: 75.470725 | CA30: 76.432726 | CB30: 77.394726 | CC30: 78.401111 | CD30: 79.407495 | CE30: 80.413879 | CF30: 81.289081 | CG30: 81.289081 | CH30: 81.289081 | CI30: 81.289081 | CJ30: 81.289081 | CK30: 81.289081 | CL30: 81.289081 | CM30: 81.289081 | CN30: 81.289081 | CO30: 81.289081 | CP30: 81.289081 | CQ30: 81.289081 | CR30: 81.289081 | CS30: 81.289081 | CT30: 81.289081 | CU30: 81.289081 | CV30: 81.289081 | CW30: 81.289081 | CX30: 81.289081
A31: datastructure | B31: WB.DATA360:DS_DATA360(1.3) | C31: I | D31: A | E31: MMR | F31: WB_WDI_ER_H2O_FWST_ZS | G31: _T | H31: _T | I31: _T | J31: PT_FRSH_WAT_RSC | K31: _Z | L31: _Z | M31: _Z | N31: _Z | O31: RATIO | P31: 2 | Q31: WB_WDI | R31: P1Y | S31: Level of water stress: freshwater withdrawal as a proportion of available freshwater resources | T31: 0 | U31: WB_WDI | V31: PU | W31: A | X31: Annual | Y31: Myanmar | Z31: Level of water stress: freshwater withdrawal as a proportion of available freshwater resources | AA31: Total | AB31: All age ranges or no breakdown by age | AC31: Total | AD31: Percentage of freshwater resources | AE31: Not Applicable | AF31: Not Applicable | AG31: Not Applicable | AH31: Not Applicable | AI31: Ratio | AJ31: Two | AK31: World Development Indicators (WDI) | AL31: Annual | AM31: Units | AN31: Normal value | AO31: Public | BO31: 4.9329609 | BP31: 4.9997717 | BQ31: 5.0665825 | BR31: 5.1333933 | BS31: 5.2002041 | BT31: 5.2670149 | BU31: 5.3333665 | BV31: 5.4001007 | BW31: 5.4674474 | BX31: 5.5342582 | BY31: 5.6003035 | BZ31: 5.6670378 | CA31: 5.733772 | CB31: 5.8015014 | CC31: 5.8015014 | CD31: 5.8015014 | CE31: 5.8015014 | CF31: 5.8015014 | CG31: 5.8015014 | CH31: 5.8015014 | CI31: 5.8015014 | CJ31: 5.8015014 | CK31: 5.8015014 | CL31: 5.8015014 | CM31: 5.8015014 | CN31: 5.8015014 | CO31: 5.8015014 | CP31: 5.8015014 | CQ31: 5.8015014 | CR31: 5.8015014 | CS31: 5.8015014 | CT31: 5.8015014 | CU31: 5.8015014 | CV31: 5.8015014 | CW31: 5.8015014 | CX31: 5.8015014
A32: datastructure | B32: WB.DATA360:DS_DATA360(1.3) | C32: I | D32: A | E32: MLT | F32: WB_WDI_ER_H2O_FWST_ZS | G32: _T | H32: _T | I32: _T | J32: PT_FRSH_WAT_RSC | K32: _Z | L32: _Z | M32: _Z | N32: _Z | O32: RATIO | P32: 2 | Q32: WB_WDI | R32: P1Y | S32: Level of water stress: freshwater withdrawal as a proportion of available freshwater resources | T32: 0 | U32: WB_WDI | V32: PU | W32: A | X32: Annual | Y32: Malta | Z32: Level of water stress: freshwater withdrawal as a proportion of available freshwater resources | AA32: Total | AB32: All age ranges or no breakdown by age | AC32: Total | AD32: Percentage of freshwater resources | AE32: Not Applicable | AF32: Not Applicable | AG32: Not Applicable | AH32: Not Applicable | AI32: Ratio | AJ32: Two | AK32: World Development Indicators (WDI) | AL32: Annual | AM32: Units | AN32: Normal value | AO32: Public | BH32: 39.60396 | BI32: 44.356436 | BJ32: 49.108911 | BK32: 53.861386 | BL32: 58.613861 | BM32: 53.267327 | BN32: 52.554455 | BO32: 51.841584 | BP32: 51.128713 | BQ32: 50.415842 | BR32: 49.70297 | BS32: 48.990099 | BT32: 48.277228 | BU32: 47.564356 | BV32: 46.851485 | BW32: 46.138614 | BX32: 49.165488 | BY32: 52.192362 | BZ32: 55.219236 | CA32: 58.24611 | CB32: 61.272984 | CC32: 64.299859 | CD32: 67.326733 | CE32: 68.435644 | CF32: 68.514851 | CG32: 70.653465 | CH32: 71.762376 | CI32: 72.871287 | CJ32: 70.891089 | CK32: 62.772277 | CL32: 80.990099 | CM32: 75.445545 | CN32: 79.405941 | CO32: 91.287129 | CP32: 89.108911 | CQ32: 82.772277 | CR32: 82.970297 | CS32: 91.089109 | CT32: 84.623003 | CU32: 80.660965 | CV32: 81.777156 | CW32: 78.467214 | CX32: 72.600008
A33: datastructure | B33: WB.DATA360:DS_DATA360(1.3) | C33: I | D33: A | E33: IDN | F33: WB_WDI_ER_H2O_FWST_ZS | G33: _T | H33: _T | I33: _T | J33: PT_FRSH_WAT_RSC | K33: _Z | L33: _Z | M33: _Z | N33: _Z | O33: RATIO | P33: 2 | Q33: WB_WDI | R33: P1Y | S33: Level of water stress: freshwater withdrawal as a proportion of available freshwater resources | T33: 0 | U33: WB_WDI | V33: PU | W33: A | X33: Annual | Y33: Indonesia | Z33: Level of water stress: freshwater withdrawal as a proportion of available freshwater resources | AA33: Total | AB33: All age ranges or no breakdown by age | AC33: Total | AD33: Percentage of freshwater resources | AE33: Not Applicable | AF33: Not Applicable | AG33: Not Applicable | AH33: Not Applicable | AI33: Ratio | AJ33: Two | AK33: World Development Indicators (WDI) | AL33: Annual | AM33: Units | AN33: Normal value | AO33: Public | BR33: 9.914139 | BS33: 10.433596 | BT33: 10.953053 | BU33: 11.47251 | BV33: 11.991967 | BW33: 12.511425 | BX33: 13.030882 | BY33: 13.550339 | BZ33: 14.069796 | CA33: 14.589253 | CB33: 15.10871 | CC33: 16.02045 | CD33: 16.93219 | CE33: 17.843929 | CF33: 18.755669 | CG33: 19.667409 | CH33: 20.579148 | CI33: 21.490888 | CJ33: 22.402628 | CK33: 23.314367 | CL33: 24.226107 | CM33: 25.137847 | CN33: 26.049587 | CO33: 26.961326 | CP33: 27.873066 | CQ33: 28.784806 | CR33: 29.696545 | CS33: 29.696545 | CT33: 29.696545 | CU33: 29.696545 | CV33: 29.696545 | CW33: 29.696545 | CX33: 29.696545
A34: datastructure | B34: WB.DATA360:DS_DATA360(1.3) | C34: I | D34: A | E34: FRA | F34: WB_WDI_ER_H2O_FWST_ZS | G34: _T | H34: _T | I34: _T | J34: PT_FRSH_WAT_RSC | K34: _Z | L34: _Z | M34: _Z | N34: _Z | O34: RATIO | P34: 2 | Q34: WB_WDI | R34: P1Y | S34: Level of water stress: freshwater withdrawal as a proportion of available freshwater resources | T34: 0 | U34: WB_WDI | V34: PU | W34: A | X34: Annual | Y34: France | Z34: Level of water stress: freshwater withdrawal as a proportion of available freshwater resources | AA34: Total | AB34: All age ranges or no breakdown by age | AC34: Total | AD34: Percentage of freshwater resources | AE34: Not Applicable | AF34: Not Applicable | AG34: Not Applicable | AH34: Not Applicable | AI34: Ratio | AJ34: Two | AK34: World Development Indicators (WDI) | AL34: Annual | AM34: Units | AN34: Normal value | AO34: Public | BH34: 27.106715 | BI34: 27.792874 | BJ34: 28.479034 | BK34: 29.165193 | BL34: 29.851353 | BM34: 30.537512 | BN34: 31.027401 | BO34: 31.51729 | BP34: 32.007179 | BQ34: 32.497067 | BR34: 32.986956 | BS34: 33.660159 | BT34: 34.333363 | BU34: 32.777204 | BV34: 31.221045 | BW34: 29.664887 | BX34: 28.108728 | BY34: 26.552569 | BZ34: 27.243573 | CA34: 27.934576 | CB34: 28.62558 | CC34: 28.474569 | CD34: 28.323558 | CE34: 28.642797 | CF34: 28.962036 | CG34: 29.281275 | CH34: 28.206251 | CI34: 27.131226 | CJ34: 25.089731 | CK34: 24.923663 | CL34: 25.017946 | CM34: 26.390615 | CN34: 24.567101 | CO34: 23.773965 | CP34: 23.896525 | CQ34: 24.613499 | CR34: 23.142782 | CS34: 23.58925 | CT34: 23.569049 | CU34: 22.946762 | CV34: 21.598137 | CW34: 21.384627 | CX34: 21.384627
A35: datastructure | B35: WB.DATA360:DS_DATA360(1.3) | C35: I | D35: A | E35: COD | F35: WB_WDI_ER_H2O_FWST_ZS | G35: _T | H35: _T | I35: _T | J35: PT_FRSH_WAT_RSC | K35: _Z | L35: _Z | M35: _Z | N35: _Z | O35: RATIO | P35: 2 | Q35: WB_WDI | R35: P1Y | S35: Level of water stress: freshwater withdrawal as a proportion of available freshwater resources | T35: 0 | U35: WB_WDI | V35: PU | W35: A | X35: Annual | Y35: Congo, Dem. Rep. | Z35: Level of water stress: freshwater withdrawal as a proportion of available freshwater resources | AA35: Total | AB35: All age ranges or no breakdown by age | AC35: Total | AD35: Percentage of freshwater resources | AE35: Not Applicable | AF35: Not Applicable | AG35: Not Applicable | AH35: Not Applicable | AI35: Ratio | AJ35: Two | AK35: World Development Indicators (WDI) | AL35: Annual | AM35: Units | AN35: Normal value | AO35: Public | BW35: 0.15801527 | BX35: 0.1651842 | BY35: 0.17235314 | BZ35: 0.17952207 | CA35: 0.18669101 | CB35: 0.19385994 | CC35: 0.20046465 | CD35: 0.20706937 | CE35: 0.21367408 | CF35: 0.22027879 | CG35: 0.22688351 | CH35: 0.22688351 | CI35: 0.22688351 | CJ35: 0.22688351 | CK35: 0.22688351 | CL35: 0.22688351 | CM35: 0.22688351 | CN35: 0.22688351 | CO35: 0.22688351 | CP35: 0.22688351 | CQ35: 0.22688351 | CR35: 0.22688351 | CS35: 0.22688351 | CT35: 0.22688351 | CU35: 0.22688351 | CV35: 0.22688351 | CW35: 0.22688351 | CX35: 0.22688351
A36: datastructure | B36: WB.DATA360:DS_DATA360(1.3) | C36: I | D36: A | E36: CYP | F36: WB_WDI_ER_H2O_FWST_ZS | G36: _T | H36: _T | I36: _T | J36: PT_FRSH_WAT_RSC | K36: _Z | L36: _Z | M36: _Z | N36: _Z | O36: RATIO | P36: 2 | Q36: WB_WDI | R36: P1Y | S36: Level of water stress: freshwater withdrawal as a proportion of available freshwater resources | T36: 0 | U36: WB_WDI | V36: PU | W36: A | X36: Annual | Y36: Cyprus | Z36: Level of water stress: freshwater withdrawal as a proportion of available freshwater resources | AA36: Total | AB36: All age ranges or no breakdown by age | AC36: Total | AD36: Percentage of freshwater resources | AE36: Not Applicable | AF36: Not Applicable | AG36: Not Applicable | AH36: Not Applicable | AI36: Ratio | AJ36: Two | AK36: World Development Indicators (WDI) | AL36: Annual | AM36: Units | AN36: Normal value | AO36: Public | BC36: 21.186441 | BD36: 21.787862 | BE36: 22.389284 | BF36: 22.990705 | BG36: 23.592127 | BH36: 24.193548 | BI36: 24.822307 | BJ36: 25.451066 | BK36: 26.079825 | BL36: 26.708584 | BM36: 27.337343 | BN36: 27.966102 | BO36: 28.758885 | BP36: 29.469656 | BQ36: 30.180426 | BR36: 30.481137 | BS36: 29.797704 | BT36: 29.11427 | BU36: 28.430837 | BV36: 27.513083 | BW36: 26.595329 | BX36: 25.677576 | BY36: 24.759822 | BZ36: 23.842068 | CA36: 22.924315 | CB36: 22.006561 | CC36: 20.495196 | CD36: 23.332422 | CE36: 23.151996 | CF36: 22.971569 | CG36: 22.791143 | CH36: 22.610716 | CI36: 22.43029 | CJ36: 21.938218 | CK36: 25.191361 | CL36: 27.460361 | CM36: 30.180426 | CN36: 34.896118 | CO36: 28.266812 | CP36: 29.661017 | CQ36: 31.711318 | CR36: 29.797704 | CS36: 29.52433 | CT36: 28.29415 | CU36: 27.610716 | CV36: 31.574631 | CW36: 32.121378 | CX36: 30.481137
